Workbook

Sheet Cover
B2: Semiconductor FP&A Forecasting and Decision Model
B3: Fictional Embedded Control Division, modeled on Microchip Technology Inc. (NASDAQ: MCHP)
B5: Simulated data created for portfolio demonstration. It does not represent nonpublic Microchip Technology information.
B6: Reported public data comes only from Microchip Technology's SEC filings (see Sources_Log). All division-level operating data is simulated and labeled as such.
B8: Business question | C8: How would changes in demand, average selling price, product mix, manufacturing yield, capacity utilization, operating costs and capital spending affect the division's revenue, operating profit and free cash flow?
B10: Model status | C10: =Checks!$C$174 -> ALL CHECKS PASS
B11: Built by | C11: scripts/build_model.py --company MCHP (config: companies/MCHP/config.toml)
B13: Tab guide
B14: Cover | C14: This page
B15: Sources_Log | C15: Source register (SEC filings) and assumptions log
B16: Assumptions | C16: Scenario selector (one cell), 9 scenario drivers, division & product inputs, seasonality
B17: Hist_Data | C17: Reported financials FY2022-FY2026, one source per row (inputs)
B18: Hist_Analysis | C18: Growth, margins, segment mix, free cash flow, working capital (formulas)
B19: Ops_Model | C19: Product x month operating model: demand, capacity, yield, inventory, revenue, cost, gross profit
B20: Revenue | C20: Monthly revenue forecast by product line, mix, quarters, FY vs FY2026 base year
B21: PnL | C21: Monthly P&L to net income; EBITDA; FY2026 base-year comparison
B22: FCF | C22: Capex and depreciation, working capital, free cash flow
B23: Budget | C23: FY2027 budget = Base scenario, locked (does not follow the selector)
B24: Actuals | C24: SIMULATED actual results Apr-Aug 2026, same operating logic
B25: Variance | C25: YTD budget vs actual: price/volume/mix, operating-profit bridge, reconciliation flags
... B28: Checks | C28: Independent checks and hand-calculable unit tests; overall status feeds this cover
B30: Color legend
B31: 1,234.5 | C31: Blue: hardcoded input (reported value or assumption)
B32: 1,234.5 | C32: Black: formula / calculation
B33: 1,234.5 | C33: Green: direct link to another tab
B34: Input | C34: Yellow fill: key assumption / cell a user may change
B36: Value classification
C37: Reported public data - transcribed from an SEC filing (source on every row)
C38: Calculated value - Excel formula on other cells
C39: User-provided assumption - logged in Sources_Log with who decided it
C40: Simulated operational data - labeled with the disclaimer above
B42: Units & conventions | C42: USD millions unless noted. Fiscal year ends March 31. Negatives in parentheses. Capex printed negative in Hist_Data, positive in analysis.

Sheet Sources_Log
A1: Source Register and Assumptions Log
A2: Every reported value traces to a source below. Every assumption is logged with who decided it.
A3: Simulated data created for portfolio demonstration. It does not represent nonpublic Microchip Technology information.
A5: Source register
A6: ID | B6: Document | C6: Accession no. | D6: Period covered | E6: URL | F6: Used for | G6: Accessed
A7: S-001 | B7: Form 10-K fiscal 2026 | C7: 0000827054-26-000016 | D7: FY2024-FY2026 income & cash flow; FY2025-FY2026 balance sheet; product lines; segments; inventory detail; Item 1 manufacturing facts | E7: https://www.sec.gov/Archives/edgar/data/827054/000082705426000016/ | F7: Historical analysis; product-mix anchor | G7: 2026-09-22
A8: S-002 | B8: Form 10-K fiscal 2024 | C8: 0000827054-24-000098 | D8: FY2022-FY2024 income & cash flow; FY2023-FY2024 balance sheet; FY2022-FY2024 product lines | E8: https://www.sec.gov/Archives/edgar/data/827054/000082705424000098/ | F8: Historical analysis; cross-filing check | G8: 2026-09-22
A9: S-003 | B9: Form 10-K fiscal 2023 | C9: 0000827054-23-000080 | D9: FY2022-FY2023 balance sheet | E9: https://www.sec.gov/Archives/edgar/data/827054/000082705423000080/ | F9: FY2022 opening working capital; cross-filing check | G9: 2026-09-22
A10: S-004 | B10: Form 10-Q Q1 fiscal 2027 | C10: 0000827054-26-000038 | D10: Quarter ended 2026-06-30 net sales by product line | E10: https://ir.microchip.com/sec-filings/all-sec-filings/content/0000827054-26-000038/mchp-20260630.htm | F10: Context for FY2027 forecast | G10: 2026-09-22
A11: S-005 | B11: Q4 & FY2026 earnings release (Exhibit 99.1) | C11: 0000827054-26-000012 | D11: Q4 FY2026 commentary: factory utilization outlook; inventory days; Fab 2 restructuring | E11: https://www.sec.gov/Archives/edgar/data/827054/000082705426000012/exhibit991q4fy26.htm | F11: Narrative context only (no values used in model yet) | G11: 2026-09-22
A13: Assumptions log
A14: ID | B14: Area | C14: Assumption | D14: Value | E14: Rationale | F14: Classification | G14: Decided by | H14: Status
A15: A-001 | B15: Scope | C15: Public company used for historical data | D15: Microchip Technology Inc (NASDAQ: MCHP) | E15: Owns wafer fabs and internal test/assembly; many MCUs are Arm-based; files 10-K/10-Q with the SEC | F15: User-provided assumption | G15: User | H15: Final
A16: A-002 | B16: Scope | C16: Historical window | D16: FY2022-FY2026 (fiscal years ending March 31) | E16: Five years covers the FY2023 peak and the FY2024-FY2025 downturn | F16: User-provided assumption | G16: Claude (delegated by user) | H16: Final
A17: A-003 | B17: Timing | C17: Forecast period | D17: FY2027 monthly: Apr-2026 to Mar-2027 (12 months) | E17: Matches Microchip's current fiscal year; lets the budget-vs-actual comparison use a realistic year-to-date | F17: User-provided assumption | G17: Claude (delegated by user) | H17: Final
A18: A-004 | B18: Timing | C18: Actuals vs forecast split | D18: Apr-2026 to Aug-2026 = simulated actuals (5 months YTD); Sep-2026 to Mar-2027 = forecast | E18: As of 22-Sep-2026 the August close would be complete; September would not | F18: User-provided assumption | G18: Claude (delegated by user) | H18: Final
A19: A-005 | B19: Timing | C19: Month convention | D19: Calendar months (Microchip's own fiscal calendar is not replicated) | E19: Simpler and auditable; stated in methodology | F19: User-provided assumption | G19: Claude (delegated by user) | H19: Final
A20: A-006 | B20: Division | C20: Fictional division | D20: "Embedded Control Division" - fictional division modeled on Microchip's business | E20: Project requires a fictional division with three product categories | F20: User-provided assumption | G20: Claude (delegated by user) | H20: Final
A21: A-007 | B21: Division | C21: Division base-year (FY2026) revenue | D21: $1,000.0M | E21: Round number; about 21% of Microchip FY2026 net sales so it is plausibly one division | F21: User-provided assumption | G21: Claude (delegated by user) | H21: Final
A22: A-008 | B22: Division | C22: Product categories | D22: 1) Mixed-signal microcontrollers 2) Analog & power management 3) FPGAs | E22: Mirror Microchip's reported product lines. FPGAs are part of Microchip's reported 'Other' line and are NOT reported separately | F22: User-provided assumption | G22: Claude (delegated by user) | H22: Final
A23: A-009 | B23: Division | C23: Base-year product mix | D23: MCU 49.9756% / Analog & power 28.1980% / FPGA 21.8264% | E23: Microchip FY2026 reported product-line sales / FY2026 net sales (S-001). FPGA share uses the whole 'Other' line as a stand-in | F23: Calculated value | G23: Claude (delegated by user) | H23: Final
A24: A-010 | B24: Labeling | C24: Simulated-data disclaimer | D24: Simulated data created for portfolio demonstration. It does not represent nonpublic Microchip Technology information. | E24: Project data rules | F24: User-provided assumption | G24: User | H24: Final
A25: A-011 | B25: Dashboard | C25: Dashboard technology | D25: Custom static web dashboard (HTML/JS) reading JSON exported from the Excel model; Excel is the single source of truth | E25: User wants a modern look instead of Power BI | F25: User-provided assumption | G25: User | H25: Final
... A51: A-037 | B51: Dashboard | C51: Risk bins on the demand/capacity heat map | D51: OK < 0.85; TIGHT 0.85-1.00; SHORT >= 1.00 (demand / good-unit capacity at full load) | E51: Test-floor vocabulary; thresholds adjustable in dashboard/template.html (binOf) | F51: User-provided assumption | G51: Claude (delegated by user) | H51: Final

Sheet Assumptions
A1: Assumptions and Scenario Controls
A2: Change ONLY the yellow selector (C6) to switch scenario. Blue = input. Every forecast tab reads the Live column.
A3: Simulated data created for portfolio demonstration. It does not represent nonpublic Microchip Technology information.
A6: ACTIVE SCENARIO (choose Downside / Base / Upside) | C6: Base | D6: =MATCH($C$6,$C$9:$E$9,0) -> 2 | E6: <- scenario index (1 = Downside, 2 = Base, 3 = Upside)
A8: A. Scenario drivers (FY2027 vs FY2026 base year)
A9: Driver | B9: Units | C9: Downside | D9: Base | E9: Upside | F9: LIVE | P9: Classification | Q9: Rationale / reference
A10: Customer demand growth | B10: % | C10: 0.05 | D10: 0.2 | E10: 0.3 | F10: =INDEX(C10:E10,1,$D$6) -> 0.2 | P10: User-provided assumption | Q10: Microchip Q1 FY2027 sales +38% YoY and Q1 run-rate +26% vs FY2026 (section B). Base takes a more cautious +20%.
A11: Average selling price change | B11: % | C11: -0.04 | D11: -0.01 | E11: 0.01 | F11: =INDEX(C11:E11,1,$D$6) -> -0.01 | P11: User-provided assumption | Q11: Mature semiconductor prices usually drift down slowly; downside = price competition as inventory clears.
A12: Manufacturing yield change (percentage points vs base-year yield) | B12: pts | C12: -0.02 | D12: 0 | E12: 0.01 | F12: =INDEX(C12:E12,1,$D$6) -> 0 | P12: User-provided assumption | Q12: Applied to each product's base-year final-test yield (section D).
A13: Capacity utilization (internal final test) | B13: % | C13: 0.7 | D13: 0.8 | E13: 0.88 | F13: =INDEX(C13:E13,1,$D$6) -> 0.8 | P13: User-provided assumption | Q13: FY2026 implied ~65% (downturn). Microchip expects 'higher internal factory utilization' (S-005).
A14: Material-cost inflation (variable cost per unit) | B14: % | C14: 0.06 | D14: 0.03 | E14: 0.01 | F14: =INDEX(C14:E14,1,$D$6) -> 0.03 | P14: User-provided assumption | Q14: Wafer, substrate and packaging cost inflation.
A15: R&D expense growth | B15: % | C15: 0.02 | D15: 0.05 | E15: 0.08 | F15: =INDEX(C15:E15,1,$D$6) -> 0.05 | P15: User-provided assumption | Q15: Microchip R&D grew +10.4% in FY2026 (section B). Downside = hiring freeze.
A16: SG&A expense growth | B16: % | C16: 0.01 | D16: 0.04 | E16: 0.06 | F16: =INDEX(C16:E16,1,$D$6) -> 0.04 | P16: User-provided assumption | Q16: Microchip SG&A grew +9.2% in FY2026 (section B).
A17: Capital expenditures (% of revenue, excl. proposed test-equipment project) | B17: % | C17: 0.02 | D17: 0.03 | E17: 0.04 | F17: =INDEX(C17:E17,1,$D$6) -> 0.03 | P17: User-provided assumption | Q17: Microchip capex 1.9% of sales FY2026, 3.7-5.8% FY2022-FY2024 (section B).
A18: Tax rate | B18: % | C18: 0.21 | D18: 0.18 | E18: 0.16 | F18: =INDEX(C18:E18,1,$D$6) -> 0.18 | P18: User-provided assumption | Q18: Microchip effective rate 13-23% in FY2022-FY2026 excl. FY2025 (section B). Downside = US statutory 21%.
A20: B. Reference points from Microchip Technology's reported history (formulas - context for the drivers above)
A21: Q1 FY2027 net sales growth vs Q1 FY2026 | F21: =Hist_Analysis!$E$51 -> 0.3804742 | P21: Calculated value | Q21: Reported public data (Hist tabs)
A22: Q1 FY2027 sales x 4 vs FY2026 net sales | F22: =Hist_Data!$D$70*4/Hist_Data!$G$7-1 -> 0.26006238 | P22: Calculated value | Q22: Reported public data (Hist tabs)
A23: Gross margin FY2026 (reported basis) | F23: =Hist_Analysis!$G$9 -> 0.57734824 | P23: Calculated value | Q23: Reported public data (Hist tabs)
A24: Gross margin FY2023 (highest in the history) | F24: =Hist_Analysis!$D$9 -> 0.67521064 | P24: Calculated value | Q24: Reported public data (Hist tabs)
A25: R&D growth FY2026 | F25: =Hist_Data!$G$10/Hist_Data!$F$10-1 -> 0.10378126 | P25: Calculated value | Q25: Reported public data (Hist tabs)
A26: SG&A growth FY2026 | F26: =Hist_Data!$G$11/Hist_Data!$F$11-1 -> 0.091630241 | P26: Calculated value | Q26: Reported public data (Hist tabs)
A27: Capex % of sales FY2026 | F27: =Hist_Analysis!$G$37 -> 0.019329104 | P27: Calculated value | Q27: Reported public data (Hist tabs)
A28: Capex % of sales, average FY2022-FY2026 | F28: =AVERAGE(Hist_Analysis!$C$37:$G$37) -> 0.039434879 | P28: Calculated value | Q28: Reported public data (Hist tabs)
A29: Effective tax rate, average FY2022-FY2026 (years shown n.m. excluded) | F29: =AVERAGE(Hist_Analysis!$C$17:$G$17) -> 0.17922279 | P29: Calculated value | Q29: Reported public data (Hist tabs)
A30: Share of test performed internally (FY2026) | F30: =Hist_Data!$G$79 -> 0.69 | P30: Calculated value | Q30: Reported public data (Hist tabs)
A32: C. Fictional Embedded Control Division - base year FY2026 (Simulated data created for portfolio demonstration. It does not represent nonpublic Microchip Technology information.)
A33: Division net revenue, FY2026 base year | B33: $m | F33: 1000 | P33: User-provided assumption | Q33: User-provided assumption. ~21% of Microchip Technology FY2026 net sales
A34: Division R&D expense, FY2026 base year | B34: $m | F34: 200 | P34: Simulated operational data | Q34: 20% of revenue. Microchip company-wide 23.0% includes corporate R&D. Used in Phase 3.
A35: Division SG&A expense, FY2026 base year | B35: $m | F35: 100 | P35: Simulated operational data | Q35: 10% of revenue. Microchip company-wide 14.3% includes corporate overhead. Used in Phase 3.
A36: Forecast start month (first month of FY2027) | F36: 46113 | P36: User-provided assumption | Q36: FY2027 = Apr-2026 to Mar-2027, calendar months
A38: D. Product inputs - base year FY2026 (simulated) and live FY2027 drivers (calculated)
A39: Input | B39: Units | C39: Mixed-signal MCUs | D39: Analog & power | E39: FPGAs | F39: Division | P39: Classification | Q39: Notes
A40: Base-year revenue mix | B40: % | C40: =Hist_Analysis!$G$20 -> 0.499756 | D40: =Hist_Analysis!$G$21 -> 0.28198001 | E40: =Hist_Analysis!$G$22 -> 0.21826399 | F40: =SUM(C40:E40) -> 1 | P40: Calculated value | Q40: Microchip Technology FY2026 reported segment mix. FPGA uses Microchip's whole 'Other' line as a stand-in (FPGAs are not reported separately).
A41: Base-year revenue | B41: $m | C41: =$F$33*$C$40 -> 499.756 | D41: =$F$33*$D$40 -> 281.98001 | E41: =$F$33*$E$40 -> 218.26399 | F41: =SUM(C41:E41) -> 1000 | P41: Calculated value | Q41: Division revenue x mix
A42: Base-year average selling price | B42: $/unit | C42: 2 | D42: 0.8 | E42: 25 | P42: Simulated operational data | Q42: Simulated. Order of magnitude typical for each product type.
A43: Base-year final-test yield | B43: % | C43: 0.92 | D43: 0.94 | E43: 0.85 | P43: Simulated operational data | Q43: Simulated. Good units / units tested. Larger FPGA die -> lower yield.
A44: Base-year variable cost per unit produced | B44: $/unit | C44: 0.31 | D44: 0.15 | E44: 4.7 | P44: Simulated operational data | Q44: Simulated. Wafer, foundry, substrate, package, test consumables per unit started.
A45: Fixed manufacturing cost per month | B45: $m/month | C45: 9.5 | D45: 5.2 | E45: 4.4 | F45: =SUM(C45:E45) -> 19.1 | P45: Simulated operational data | Q45: Simulated. Factory overhead, depreciation, fab/test labor. Same in base year and FY2027.
A46: Internal final-test capacity | B46: m units/month | C46: 35 | D46: 46 | E46: 1.3 | P46: Simulated operational data | Q46: Simulated. Capacity = units the internal test floor can process per month (A-016).
...

Sheet Hist_Data
A1: Historical Data - Microchip Technology (reported)
A2: USD millions unless noted. Fiscal years end March 31. Blue = hardcoded reported value from SEC filing.
A3: Simulated data created for portfolio demonstration. It does not represent nonpublic Microchip Technology information. (This tab contains reported public data and calculated values only.)
A5: Line item | B5: Units | C5: FY2022 | D5: FY2023 | E5: FY2024 | F5: FY2025 | G5: FY2026 | H5: Classification | I5: Source (filing, statement page) | J5: Notes | K5: line_id
A6: Income statement
A7: Net sales | B7: $m | C7: 6820.9 | D7: 8438.7 | E7: 7634.4 | F7: 4401.6 | G7: 4713.1 | H7: Reported public data | I7: S-002 10-K FY2024 R5.htm; S-001 10-K FY2026 R5.htm | K7: net_sales
A8: Cost of sales | B8: $m | C8: 2371.3 | D8: 2740.8 | E8: 2638.7 | F8: 1933.7 | G8: 1992 | H8: Reported public data | I8: S-002 10-K FY2024 R5.htm; S-001 10-K FY2026 R5.htm | K8: cost_of_sales
A9: Gross profit | B9: $m | C9: 4449.6 | D9: 5697.9 | E9: 4995.7 | F9: 2467.9 | G9: 2721.1 | H9: Reported public data | I9: S-002 10-K FY2024 R5.htm; S-001 10-K FY2026 R5.htm | K9: gross_profit
A10: Research and development | B10: $m | C10: 989.1 | D10: 1118.3 | E10: 1097.4 | F10: 983.8 | G10: 1085.9 | H10: Reported public data | I10: S-002 10-K FY2024 R5.htm; S-001 10-K FY2026 R5.htm | K10: rd
A11: Selling, general and administrative | B11: $m | C11: 718.9 | D11: 797.7 | E11: 734.2 | F11: 617.7 | G11: 674.3 | H11: Reported public data | I11: S-002 10-K FY2024 R5.htm; S-001 10-K FY2026 R5.htm | K11: sga
A12: Amortization of acquired intangible assets | B12: $m | C12: 862.5 | D12: 669.9 | E12: 605.4 | F12: 490.9 | G12: 431.1 | H12: Reported public data | I12: S-002 10-K FY2024 R5.htm; S-001 10-K FY2026 R5.htm | K12: other_opex:amortization
A13: Special charges (income) and other, net | B13: $m | C13: 29.5 | D13: -4 | E13: -12.3 | F13: 79.2 | G13: 39.7 | H13: Reported public data | I13: S-002 10-K FY2024 R5.htm; S-001 10-K FY2026 R5.htm | J13: Printed '(income) charges' in FY2024 10-K; negative = income. | K13: other_opex:special
A14: Operating expenses (total) | B14: $m | C14: 2600 | D14: 2581.9 | E14: 2424.7 | F14: 2171.6 | G14: 2231 | H14: Reported public data | I14: S-002 10-K FY2024 R5.htm; S-001 10-K FY2026 R5.htm | K14: total_opex
A15: Operating income | B15: $m | C15: 1849.6 | D15: 3116 | E15: 2571 | F15: 296.3 | G15: 490.1 | H15: Reported public data | I15: S-002 10-K FY2024 R5.htm; S-001 10-K FY2026 R5.htm | K15: operating_income
A16: Interest income | B16: $m | C16: 0.5 | D16: 2.1 | E16: 7.6 | F16: 9.2 | G16: 11.4 | H16: Reported public data | I16: S-002 10-K FY2024 R5.htm; S-001 10-K FY2026 R5.htm | K16: nonop:interest_income
A17: Interest expense | B17: $m | C17: -257 | D17: -203.9 | E17: -198.3 | F17: -259.2 | G17: -221.3 | H17: Reported public data | I17: S-002 10-K FY2024 R5.htm; S-001 10-K FY2026 R5.htm | K17: nonop:interest_expense
A18: Loss on settlement of debt | B18: $m | C18: -113.4 | D18: -8.3 | E18: -12.2 | F18: -1.7 | G18: 0 | H18: Reported public data | I18: S-002 10-K FY2024 R5.htm; S-001 10-K FY2026 R5.htm | K18: nonop:loss_on_debt
A19: Other income (loss), net | B19: $m | C19: 2.8 | D19: 3.8 | E19: -2.2 | F19: -5.7 | G19: -6.7 | H19: Reported public data | I19: S-002 10-K FY2024 R5.htm; S-001 10-K FY2026 R5.htm | K19: nonop:other
A20: Income before income taxes | B20: $m | C20: 1482.5 | D20: 2909.7 | E20: 2365.9 | F20: 38.9 | G20: 273.5 | H20: Reported public data | I20: S-002 10-K FY2024 R5.htm; S-001 10-K FY2026 R5.htm | K20: pretax_income
A21: Income tax provision | B21: $m | C21: 197 | D21: 672 | E21: 459 | F21: 39.4 | G21: 43.5 | H21: Reported public data | I21: S-002 10-K FY2024 R5.htm; S-001 10-K FY2026 R5.htm | K21: income_tax
A22: Net income (loss) | B22: $m | C22: 1285.5 | D22: 2237.7 | E22: 1906.9 | F22: -0.5 | G22: 230 | H22: Reported public data | I22: S-002 10-K FY2024 R5.htm; S-001 10-K FY2026 R5.htm | K22: net_income
A23: Dividends on Series A Preferred Stock | B23: $m | E23: 0 | F23: -2.2 | G23: -111.2 | H23: Reported public data | I23: S-001 10-K FY2026 R5.htm | K23: memo:preferred_dividends
A24: Net income (loss) attributable to common stockholders | B24: $m | E24: 1906.9 | F24: -2.7 | G24: 118.8 | H24: Reported public data | I24: S-001 10-K FY2026 R5.htm | K24: memo:net_income_common
A25: Net sales by reported segment / product line
A26: Mixed-signal Microcontrollers | B26: $m | C26: 3814.8 | D26: 4755.7 | E26: 4272.4 | F26: 2249.7 | G26: 2355.4 | H26: Reported public data | I26: S-002 10-K FY2024 R45.htm; S-001 10-K FY2026 R43.htm | K26: segment:mixed_signal_microcontrollers
A27: Analog | B27: $m | C27: 1939.1 | D27: 2376.9 | E27: 2016.4 | F27: 1157 | G27: 1329 | H27: Reported public data | I27: S-002 10-K FY2024 R45.htm; S-001 10-K FY2026 R43.htm | K27: segment:analog
A28: Other (incl. FPGA, licensing, memory, timing) | B28: $m | C28: 1067 | D28: 1306.1 | E28: 1345.6 | F28: 994.9 | G28: 1028.7 | H28: Reported public data | I28: S-002 10-K FY2024 R45.htm; S-001 10-K FY2026 R43.htm | J28: Per 10-K Item 1: FPGA, licensing royalties & IP sales, engineering services, memory, timing systems, manufacturing services, legacy ASICs, aerospace. FPGA not reported separately. | K28: segment:other
A29: Other segment disclosures
A30: Semiconductor products - net sales | B30: $m | E30: 7531.1 | F30: 4270.5 | G30: 4549.3 | H30: Reported public data | I30: S-001 10-K FY2026 R45.htm | J30: Segment table first disclosed in this form in S-001 (covers FY2024-FY2026 only). | K30: segment_info:semis_sales
A31: Semiconductor products - gross profit | B31: $m | E31: 4892.4 | F31: 2336.8 | G31: 2557.3 | H31: Reported public data | I31: S-001 10-K FY2026 R45.htm | K31: segment_info:semis_gross_profit
A32: Technology licensing - net sales | B32: $m | E32: 103.3 | F32: 131.1 | G32: 163.8 | H32: Reported public data | I32: S-001 10-K FY2026 R45.htm | J32: Technology licensing has no cost of sales in the segment table. | K32: segment_info:licensing_sales
A33: Cash flow statement (selected lines)
A34: Net income (loss) | B34: $m | C34: 1285.5 | D34: 2237.7 | E34: 1906.9 | F34: -0.5 | G34: 230 | H34: Reported public data | I34: S-002 10-K FY2024 R7.htm; S-001 10-K FY2026 R7.htm | K34: cf:net_income
A35: Depreciation and amortization | B35: $m | C35: 1143.5 | D35: 998.4 | E35: 879.5 | F35: 750.1 | G35: 689.3 | H35: Reported public data | I35: S-002 10-K FY2024 R7.htm; S-001 10-K FY2026 R7.htm | K35: cf:da
A36: Share-based compensation expense | B36: $m | C36: 210.2 | D36: 170.4 | E36: 177.5 | F36: 180.4 | G36: 255.4 | H36: Reported public data | I36: S-002 10-K FY2024 R7.htm; S-001 10-K FY2026 R7.htm | K36: cf:sbc
A37: (Increase) decrease in accounts receivable | B37: $m | C37: -74.9 | D37: -232.7 | E37: 161.6 | F37: 454 | G37: -204.5 | H37: Reported public data | I37: S-002 10-K FY2024 R7.htm; S-001 10-K FY2026 R7.htm | K37: wc:receivables
A38: Decrease (increase) in inventories | B38: $m | C38: -177.8 | D38: -483.2 | E38: 12.8 | F38: 31.6 | G38: 264.3 | H38: Reported public data | I38: S-002 10-K FY2024 R7.htm; S-001 10-K FY2026 R7.htm | K38: wc:inventories
A39: Increase (decrease) in accounts payable and accrued liabilities | B39: $m | C39: 192.7 | D39: 323.4 | E39: -148.4 | F39: -345.6 | G39: 26 | H39: Reported public data | I39: S-002 10-K FY2024 R7.htm; S-001 10-K FY2026 R7.htm | K39: wc:payables_accrued
A40: Change in other assets and liabilities | B40: $m | C40: 79.4 | D40: 404.5 | E40: -64.2 | F40: -38.1 | G40: -105.8 | H40: Reported public data | I40: S-002 10-K FY2024 R7.htm; S-001 10-K FY2026 R7.htm | K40: wc:other
A41: Change in income tax payable | B41: $m | C41: 14.8 | D41: -28 | E41: -38.5 | F41: -1.8 | G41: -147.7 | H41: Reported public data | I41: S-002 10-K FY2024 R7.htm; S-001 10-K FY2026 R7.htm | K41: wc:income_tax
...

Sheet Hist_Analysis
A1: Historical Financial Analysis - Microchip Technology
A2: All figures are formulas on Hist_Data. Green = direct link to Hist_Data; black = calculation.
A3: Simulated data created for portfolio demonstration. It does not represent nonpublic Microchip Technology information. (This tab contains reported public data and calculated values only.)
A5: Metric | B5: Units | C5: FY2022 | D5: FY2023 | E5: FY2024 | F5: FY2025 | G5: FY2026 | H5: Classification | I5: Formula / definition
A6: Growth and profitability
A7: Net sales | B7: $m | C7: =Hist_Data!$C$7 -> 6820.9 | D7: =Hist_Data!$D$7 -> 8438.7 | E7: =Hist_Data!$E$7 -> 7634.4 | F7: =Hist_Data!$F$7 -> 4401.6 | G7: =Hist_Data!$G$7 -> 4713.1 | H7: Calculated value | I7: Link: Hist_Data net sales
A8: Net sales growth | B8: % | C8: n/a | D8: =IFERROR(Hist_Data!$D$7/Hist_Data!$C$7-1,"") -> 0.23718278 | E8: =IFERROR(Hist_Data!$E$7/Hist_Data!$D$7-1,"") -> -0.095310889 | F8: =IFERROR(Hist_Data!$F$7/Hist_Data!$E$7-1,"") -> -0.42345174 | G8: =IFERROR(Hist_Data!$G$7/Hist_Data!$F$7-1,"") -> 0.07076972 | H8: Calculated value | I8: Net sales / prior-year net sales - 1
A9: Gross margin | B9: % | C9: =IFERROR(Hist_Data!$C$9/Hist_Data!$C$7,"") -> 0.65234793 | D9: =IFERROR(Hist_Data!$D$9/Hist_Data!$D$7,"") -> 0.67521064 | E9: =IFERROR(Hist_Data!$E$9/Hist_Data!$E$7,"") -> 0.65436708 | F9: =IFERROR(Hist_Data!$F$9/Hist_Data!$F$7,"") -> 0.56068248 | G9: =IFERROR(Hist_Data!$G$9/Hist_Data!$G$7,"") -> 0.57734824 | H9: Calculated value | I9: Gross profit / net sales
A10: R&D % of sales | B10: % | C10: =IFERROR(Hist_Data!$C$10/Hist_Data!$C$7,"") -> 0.14501019 | D10: =IFERROR(Hist_Data!$D$10/Hist_Data!$D$7,"") -> 0.13252041 | E10: =IFERROR(Hist_Data!$E$10/Hist_Data!$E$7,"") -> 0.14374411 | F10: =IFERROR(Hist_Data!$F$10/Hist_Data!$F$7,"") -> 0.22350963 | G10: =IFERROR(Hist_Data!$G$10/Hist_Data!$G$7,"") -> 0.23040037 | H10: Calculated value | I10: Research and development / net sales
A11: SG&A % of sales | B11: % | C11: =IFERROR(Hist_Data!$C$11/Hist_Data!$C$7,"") -> 0.10539665 | D11: =IFERROR(Hist_Data!$D$11/Hist_Data!$D$7,"") -> 0.094528778 | E11: =IFERROR(Hist_Data!$E$11/Hist_Data!$E$7,"") -> 0.096169968 | F11: =IFERROR(Hist_Data!$F$11/Hist_Data!$F$7,"") -> 0.14033533 | G11: =IFERROR(Hist_Data!$G$11/Hist_Data!$G$7,"") -> 0.14306932 | H11: Calculated value | I11: SG&A / net sales
A12: Operating margin (GAAP) | B12: % | C12: =IFERROR(Hist_Data!$C$15/Hist_Data!$C$7,"") -> 0.27116656 | D12: =IFERROR(Hist_Data!$D$15/Hist_Data!$D$7,"") -> 0.36925119 | E12: =IFERROR(Hist_Data!$E$15/Hist_Data!$E$7,"") -> 0.33676517 | F12: =IFERROR(Hist_Data!$F$15/Hist_Data!$F$7,"") -> 0.06731643 | G12: =IFERROR(Hist_Data!$G$15/Hist_Data!$G$7,"") -> 0.10398676 | H12: Calculated value | I12: Operating income / net sales
A13: Other operating items (sum of reported components) | B13: $m | C13: =(N(Hist_Data!$C$12)+N(Hist_Data!$C$13)) -> 892 | D13: =(N(Hist_Data!$D$12)+N(Hist_Data!$D$13)) -> 665.9 | E13: =(N(Hist_Data!$E$12)+N(Hist_Data!$E$13)) -> 593.1 | F13: =(N(Hist_Data!$F$12)+N(Hist_Data!$F$13)) -> 570.1 | G13: =(N(Hist_Data!$G$12)+N(Hist_Data!$G$13)) -> 470.8 | H13: Calculated value | I13: Sum of: amortization of acquired intangible assets, special charges (income) and other, net
A14: Operating income before other operating items | B14: $m | C14: =Hist_Data!$C$15+$C$13 -> 2741.6 | D14: =Hist_Data!$D$15+$D$13 -> 3781.9 | E14: =Hist_Data!$E$15+$E$13 -> 3164.1 | F14: =Hist_Data!$F$15+$F$13 -> 866.4 | G14: =Hist_Data!$G$15+$G$13 -> 960.9 | H14: Calculated value | I14: Operating income + other operating items (amortization of acquired intangible assets, special charges (income) and other, net). Analyst calculation - NOT Microchip Technology's reported non-GAAP measure.
A15: Margin before other operating items | B15: % | C15: =IFERROR($C$14/Hist_Data!$C$7,"") -> 0.40194109 | D15: =IFERROR($D$14/Hist_Data!$D$7,"") -> 0.44816145 | E15: =IFERROR($E$14/Hist_Data!$E$7,"") -> 0.414453 | F15: =IFERROR($F$14/Hist_Data!$F$7,"") -> 0.19683751 | G15: =IFERROR($G$14/Hist_Data!$G$7,"") -> 0.20387855 | H15: Calculated value | I15: Row above / net sales. Closest proxy for a product division's operating margin.
A16: Net margin | B16: % | C16: =IFERROR(Hist_Data!$C$22/Hist_Data!$C$7,"") -> 0.18846487 | D16: =IFERROR(Hist_Data!$D$22/Hist_Data!$D$7,"") -> 0.26517118 | E16: =IFERROR(Hist_Data!$E$22/Hist_Data!$E$7,"") -> 0.24977732 | F16: =IFERROR(Hist_Data!$F$22/Hist_Data!$F$7,"") -> -0.00011359506 | G16: =IFERROR(Hist_Data!$G$22/Hist_Data!$G$7,"") -> 0.048800153 | H16: Calculated value | I16: Net income / net sales
A17: Effective tax rate | B17: % | C17: =IF(ABS(Hist_Data!$C$20)<0.02*Hist_Data!$C$7,"n.m.",IFERROR(Hist_Data!$C$21/Hist_Data!$C$20,"")) -> 0.13288364 | D17: =IF(ABS(Hist_Data!$D$20)<0.02*Hist_Data!$D$7,"n.m.",IFERROR(Hist_Data!$D$21/Hist_Data!$D$20,"")) -> 0.23095164 | E17: =IF(ABS(Hist_Data!$E$20)<0.02*Hist_Data!$E$7,"n.m.",IFERROR(Hist_Data!$E$21/Hist_Data!$E$20,"")) -> 0.19400651 | F17: =IF(ABS(Hist_Data!$F$20)<0.02*Hist_Data!$F$7,"n.m.",IFERROR(Hist_Data!$F$21/Hist_Data!$F$20,"")) -> n.m. | G17: =IF(ABS(Hist_Data!$G$20)<0.02*Hist_Data!$G$7,"n.m.",IFERROR(Hist_Data!$G$21/Hist_Data!$G$20,"")) -> 0.15904936 | H17: Calculated value | I17: Income tax / income before taxes. Shows n.m. (not meaningful) when pre-tax income is under 2% of sales.
A18: Incremental gross margin (change in GP / change in sales) | B18: % | C18: n/a | D18: =IFERROR((Hist_Data!$D$9-Hist_Data!$C$9)/(Hist_Data!$D$7-Hist_Data!$C$7),"") -> 0.77160341 | E18: =IFERROR((Hist_Data!$E$9-Hist_Data!$D$9)/(Hist_Data!$E$7-Hist_Data!$D$7),"") -> 0.87305732 | F18: =IFERROR((Hist_Data!$F$9-Hist_Data!$E$9)/(Hist_Data!$F$7-Hist_Data!$E$7),"") -> 0.78192279 | G18: =IFERROR((Hist_Data!$G$9-Hist_Data!$F$9)/(Hist_Data!$G$7-Hist_Data!$F$7),"") -> 0.81284109 | H18: Calculated value | I18: Shows operating leverage: how much gross profit moved per $1 of sales change (fixed-cost absorption)
A19: Reported segment / product-line mix and growth
A20: Mixed-signal Microcontrollers - share of net sales | B20: % | C20: =IFERROR(Hist_Data!$C$26/Hist_Data!$C$7,"") -> 0.55928103 | D20: =IFERROR(Hist_Data!$D$26/Hist_Data!$D$7,"") -> 0.56355837 | E20: =IFERROR(Hist_Data!$E$26/Hist_Data!$E$7,"") -> 0.55962486 | F20: =IFERROR(Hist_Data!$F$26/Hist_Data!$F$7,"") -> 0.5111096 | G20: =IFERROR(Hist_Data!$G$26/Hist_Data!$G$7,"") -> 0.499756 | H20: Calculated value | I20: Mixed-signal Microcontrollers sales / net sales
A21: Analog - share of net sales | B21: % | C21: =IFERROR(Hist_Data!$C$27/Hist_Data!$C$7,"") -> 0.284288 | D21: =IFERROR(Hist_Data!$D$27/Hist_Data!$D$7,"") -> 0.28166661 | E21: =IFERROR(Hist_Data!$E$27/Hist_Data!$E$7,"") -> 0.2641203 | F21: =IFERROR(Hist_Data!$F$27/Hist_Data!$F$7,"") -> 0.26285896 | G21: =IFERROR(Hist_Data!$G$27/Hist_Data!$G$7,"") -> 0.28198001 | H21: Calculated value | I21: Analog sales / net sales
A22: Other (incl. FPGA, licensing, memory, timing) - share of net sales | B22: % | C22: =IFERROR(Hist_Data!$C$28/Hist_Data!$C$7,"") -> 0.15643097 | D22: =IFERROR(Hist_Data!$D$28/Hist_Data!$D$7,"") -> 0.15477502 | E22: =IFERROR(Hist_Data!$E$28/Hist_Data!$E$7,"") -> 0.17625485 | F22: =IFERROR(Hist_Data!$F$28/Hist_Data!$F$7,"") -> 0.22603144 | G22: =IFERROR(Hist_Data!$G$28/Hist_Data!$G$7,"") -> 0.21826399 | H22: Calculated value | I22: Other (incl. FPGA, licensing, memory, timing) sales / net sales
A23: Mix total (must equal 100%) | B23: % | C23: =$C$20+$C$21+$C$22 -> 1 | D23: =$D$20+$D$21+$D$22 -> 1 | E23: =$E$20+$E$21+$E$22 -> 1 | F23: =$F$20+$F$21+$F$22 -> 1 | G23: =$G$20+$G$21+$G$22 -> 1 | H23: Calculated value | I23: Sum of the segment shares
A24: Mixed-signal Microcontrollers - growth | B24: % | C24: n/a | D24: =IFERROR(Hist_Data!$D$26/Hist_Data!$C$26-1,"") -> 0.24664465 | E24: =IFERROR(Hist_Data!$E$26/Hist_Data!$D$26-1,"") -> -0.10162542 | F24: =IFERROR(Hist_Data!$F$26/Hist_Data!$E$26-1,"") -> -0.47343414 | G24: =IFERROR(Hist_Data!$G$26/Hist_Data!$F$26-1,"") -> 0.046984042 | H24: Calculated value | I24: Mixed-signal Microcontrollers sales / prior year - 1
A25: Analog - growth | B25: % | C25: n/a | D25: =IFERROR(Hist_Data!$D$27/Hist_Data!$C$27-1,"") -> 0.22577484 | E25: =IFERROR(Hist_Data!$E$27/Hist_Data!$D$27-1,"") -> -0.15166814 | F25: =IFERROR(Hist_Data!$F$27/Hist_Data!$E$27-1,"") -> -0.42620512 | G25: =IFERROR(Hist_Data!$G$27/Hist_Data!$F$27-1,"") -> 0.14866033 | H25: Calculated value | I25: Analog sales / prior year - 1
A26: Other (incl. FPGA, licensing, memory, timing) - growth | B26: % | C26: n/a | D26: =IFERROR(Hist_Data!$D$28/Hist_Data!$C$28-1,"") -> 0.22408622 | E26: =IFERROR(Hist_Data!$E$28/Hist_Data!$D$28-1,"") -> 0.030242707 | F26: =IFERROR(Hist_Data!$F$28/Hist_Data!$E$28-1,"") -> -0.26062723 | G26: =IFERROR(Hist_Data!$G$28/Hist_Data!$F$28-1,"") -> 0.033973264 | H26: Calculated value | I26: Other (incl. FPGA, licensing, memory, timing) sales / prior year - 1
A27: Cash flow and free cash flow (project definition)
A28: Net income | B28: $m | C28: =Hist_Data!$C$22 -> 1285.5 | D28: =Hist_Data!$D$22 -> 2237.7 | E28: =Hist_Data!$E$22 -> 1906.9 | F28: =Hist_Data!$F$22 -> -0.5 | G28: =Hist_Data!$G$22 -> 230 | H28: Calculated value | I28: Link: Hist_Data net income
A29: Depreciation and amortization | B29: $m | C29: =Hist_Data!$C$35 -> 1143.5 | D29: =Hist_Data!$D$35 -> 998.4 | E29: =Hist_Data!$E$35 -> 879.5 | F29: =Hist_Data!$F$35 -> 750.1 | G29: =Hist_Data!$G$35 -> 689.3 | H29: Calculated value | I29: Link: Hist_Data D&A (cash flow statement)
A30: Capital expenditures (positive = spend) | B30: $m | C30: =-Hist_Data!$C$43 -> 370.1 | D30: =-Hist_Data!$D$43 -> 486.2 | E30: =-Hist_Data!$E$43 -> 285.1 | F30: =-Hist_Data!$F$43 -> 126 | G30: =-Hist_Data!$G$43 -> 91.1 | H30: Calculated value | I30: Negative of capex as printed. Cash-flow statement prints capex negative.
A31: Increase in working capital | B31: $m | C31: =-(N(Hist_Data!$C$37)+N(Hist_Data!$C$38)+N(Hist_Data!$C$39)+N(Hist_Data!$C$40)+N(Hist_Data!$C$41)) -> -34.2 | D31: =-(N(Hist_Data!$D$37)+N(Hist_Data!$D$38)+N(Hist_Data!$D$39)+N(Hist_Data!$D$40)+N(Hist_Data!$D$41)) -> 16 | E31: =-(N(Hist_Data!$E$37)+N(Hist_Data!$E$38)+N(Hist_Data!$E$39)+N(Hist_Data!$E$40)+N(Hist_Data!$E$41)) -> 76.7 | F31: =-(N(Hist_Data!$F$37)+N(Hist_Data!$F$38)+N(Hist_Data!$F$39)+N(Hist_Data!$F$40)+N(Hist_Data!$F$41)) -> -100.1 | G31: =-(N(Hist_Data!$G$37)+N(Hist_Data!$G$38)+N(Hist_Data!$G$39)+N(Hist_Data!$G$40)+N(Hist_Data!$G$41)) -> 167.7 | H31: Calculated value | I31: Negative of the sum of the 5 cash-flow working-capital lines. Positive = cash absorbed by working capital.
A32: Free cash flow (project definition) | B32: $m | C32: =$C$28+$C$29-$C$30-$C$31 -> 2093.1 | D32: =$D$28+$D$29-$D$30-$D$31 -> 2733.9 | E32: =$E$28+$E$29-$E$30-$E$31 -> 2424.6 | F32: =$F$28+$F$29-$F$30-$F$31 -> 723.7 | G32: =$G$28+$G$29-$G$30-$G$31 -> 660.5 | H32: Calculated value | I32: Net income + D&A - capex - increase in working capital (project formula)
A33: Other non-cash items in CFO (SBC, deferred tax, other) | B33: $m | C33: =Hist_Data!$C$42-$C$28-$C$29+$C$31 -> 379.5 | D33: =Hist_Data!$D$42-$D$28-$D$29+$D$31 -> 400.9 | E33: =Hist_Data!$E$42-$E$28-$E$29+$E$31 -> 183 | F33: =Hist_Data!$F$42-$F$28-$F$29+$F$31 -> 48.4 | G33: =Hist_Data!$G$42-$G$28-$G$29+$G$31 -> 210.5 | H33: Calculated value | I33: CFO - net income - D&A + increase in WC. Explains the gap to the CFO-based FCF below.
A34: Free cash flow (CFO - capex, common market definition) | B34: $m | C34: =Hist_Data!$C$42-$C$30 -> 2472.6 | D34: =Hist_Data!$D$42-$D$30 -> 3134.8 | E34: =Hist_Data!$E$42-$E$30 -> 2607.6 | F34: =Hist_Data!$F$42-$F$30 -> 772.1 | G34: =Hist_Data!$G$42-$G$30 -> 871 | H34: Calculated value | I34: Net cash from operations - capex. Reconciles to project FCF + other non-cash items (see Checks).
A35: FCF margin (project definition) | B35: % | C35: =IFERROR($C$32/Hist_Data!$C$7,"") -> 0.30686566 | D35: =IFERROR($D$32/Hist_Data!$D$7,"") -> 0.3239717 | E35: =IFERROR($E$32/Hist_Data!$E$7,"") -> 0.31758881 | F35: =IFERROR($F$32/Hist_Data!$F$7,"") -> 0.16441748 | G35: =IFERROR($G$32/Hist_Data!$G$7,"") -> 0.14014131 | H35: Calculated value | I35: Project FCF / net sales
A36: FCF conversion (project FCF / net income) | B36: x | C36: =IF(ABS($C$28)<0.02*Hist_Data!$C$7,"n.m.",IFERROR($C$32/$C$28,"")) -> 1.628238 | D36: =IF(ABS($D$28)<0.02*Hist_Data!$D$7,"n.m.",IFERROR($D$32/$D$28,"")) -> 1.2217455 | E36: =IF(ABS($E$28)<0.02*Hist_Data!$E$7,"n.m.",IFERROR($E$32/$E$28,"")) -> 1.2714878 | F36: =IF(ABS($F$28)<0.02*Hist_Data!$F$7,"n.m.",IFERROR($F$32/$F$28,"")) -> n.m. | G36: =IF(ABS($G$28)<0.02*Hist_Data!$G$7,"n.m.",IFERROR($G$32/$G$28,"")) -> 2.8717391 | H36: Calculated value | I36: Project FCF / net income. Shows n.m. when net income is under 2% of sales.
A37: Capex % of sales | B37: % | C37: =IFERROR($C$30/Hist_Data!$C$7,"") -> 0.054259702 | D37: =IFERROR($D$30/Hist_Data!$D$7,"") -> 0.057615509 | E37: =IFERROR($E$30/Hist_Data!$E$7,"") -> 0.037344127 | F37: =IFERROR($F$30/Hist_Data!$F$7,"") -> 0.028625954 | G37: =IFERROR($G$30/Hist_Data!$G$7,"") -> 0.019329104 | H37: Calculated value | I37: Capex / net sales - anchor for the forecast capex assumption
A38: D&A % of sales | B38: % | C38: =IFERROR(Hist_Data!$C$35/Hist_Data!$C$7,"") -> 0.1676465 | D38: =IFERROR(Hist_Data!$D$35/Hist_Data!$D$7,"") -> 0.11831206 | E38: =IFERROR(Hist_Data!$E$35/Hist_Data!$E$7,"") -> 0.11520224 | F38: =IFERROR(Hist_Data!$F$35/Hist_Data!$F$7,"") -> 0.1704153 | G38: =IFERROR(Hist_Data!$G$35/Hist_Data!$G$7,"") -> 0.14625194 | H38: Calculated value | I38: D&A / net sales
A39: Share-based compensation % of sales | B39: % | C39: =IFERROR(Hist_Data!$C$36/Hist_Data!$C$7,"") -> 0.030817048 | D39: =IFERROR(Hist_Data!$D$36/Hist_Data!$D$7,"") -> 0.020192684 | E39: =IFERROR(Hist_Data!$E$36/Hist_Data!$E$7,"") -> 0.023250026 | F39: =IFERROR(Hist_Data!$F$36/Hist_Data!$F$7,"") -> 0.040985096 | G39: =IFERROR(Hist_Data!$G$36/Hist_Data!$G$7,"") -> 0.054189387 | H39: Calculated value | I39: SBC / net sales
A40: Capex / depreciation & amortization | B40: x | C40: =IFERROR($C$30/Hist_Data!$C$35,"") -> 0.32365544 | D40: =IFERROR($D$30/Hist_Data!$D$35,"") -> 0.48697917 | E40: =IFERROR($E$30/Hist_Data!$E$35,"") -> 0.32416146 | F40: =IFERROR($F$30/Hist_Data!$F$35,"") -> 0.1679776 | G40: =IFERROR($G$30/Hist_Data!$G$35,"") -> 0.13216306 | H40: Calculated value | I40: <1.0x means spending less than D&A (asset base shrinking or amortization-heavy D&A)
A41: Working capital and asset efficiency (year-end balances)
...

Sheet Ops_Model
A1: Product Operating Model - FY2027 monthly (active scenario)
A2: Units in millions, money in $m, prices in $/unit. Every row traces to Assumptions. Black = formula.
A3: Simulated data created for portfolio demonstration. It does not represent nonpublic Microchip Technology information.
A4: Scenario shown: | B4: =Assumptions!$C$6 -> Base
A6: Line item | B6: Units | C6: =Assumptions!C$71 -> 46113 | D6: =Assumptions!D$71 -> 46143 | E6: =Assumptions!E$71 -> 46174 | F6: =Assumptions!F$71 -> 46204 | G6: =Assumptions!G$71 -> 46235 | H6: =Assumptions!H$71 -> 46266 | I6: =Assumptions!I$71 -> 46296 | J6: =Assumptions!J$71 -> 46327 | ... N6: =Assumptions!N$71 -> 46447 | O6: FY2027 | P6: Classification | Q6: Formula
A7: Mixed-signal microcontrollers - Simulated data created for portfolio demonstration. It does not represent nonpublic Microchip Technology information.
A8: Seasonality factor | B8: x | C8: =Assumptions!C$72 -> 0.96 | D8: =Assumptions!D$72 -> 0.98 | E8: =Assumptions!E$72 -> 1.02 | F8: =Assumptions!F$72 -> 0.97 | G8: =Assumptions!G$72 -> 0.99 | H8: =Assumptions!H$72 -> 1.04 | I8: =Assumptions!I$72 -> 1.03 | J8: =Assumptions!J$72 -> 1.01 | ... N8: =Assumptions!N$72 -> 1.08 | O8: =SUM(C8:N8) -> 12 | P8: Calculated value (simulated inputs) | Q8: Link: Assumptions section E
A9: Customer demand | B9: m units | C9: =Assumptions!$C$62*C8/12 -> 23.988288 | D9: =Assumptions!$C$62*D8/12 -> 24.488044 | E9: =Assumptions!$C$62*E8/12 -> 25.487556 | F9: =Assumptions!$C$62*F8/12 -> 24.238166 | G9: =Assumptions!$C$62*G8/12 -> 24.737922 | H9: =Assumptions!$C$62*H8/12 -> 25.987312 | I9: =Assumptions!$C$62*I8/12 -> 25.737434 | J9: =Assumptions!$C$62*J8/12 -> 25.237678 | ... N9: =Assumptions!$C$62*N8/12 -> 26.986824 | O9: =SUM(C9:N9) -> 299.8536 | P9: Calculated value (simulated inputs) | Q9: FY2027 demand x seasonality / 12
A10: Internal final-test capacity | B10: m units | C10: =Assumptions!$C$46 -> 35 | D10: =Assumptions!$C$46 -> 35 | E10: =Assumptions!$C$46 -> 35 | F10: =Assumptions!$C$46 -> 35 | G10: =Assumptions!$C$46 -> 35 | H10: =Assumptions!$C$46 -> 35 | I10: =Assumptions!$C$46 -> 35 | J10: =Assumptions!$C$46 -> 35 | ... N10: =Assumptions!$C$46 -> 35 | O10: =SUM(C10:N10) -> 420 | P10: Calculated value (simulated inputs) | Q10: Monthly capacity (Assumptions D)
A11: Capacity utilization | B11: % | C11: =Assumptions!$C$65 -> 0.8 | D11: =Assumptions!$C$65 -> 0.8 | E11: =Assumptions!$C$65 -> 0.8 | F11: =Assumptions!$C$65 -> 0.8 | G11: =Assumptions!$C$65 -> 0.8 | H11: =Assumptions!$C$65 -> 0.8 | I11: =Assumptions!$C$65 -> 0.8 | J11: =Assumptions!$C$65 -> 0.8 | ... N11: =Assumptions!$C$65 -> 0.8 | O11: =IFERROR(O12/O10,0) -> 0.8 | P11: Calculated value (simulated inputs) | Q11: Scenario utilization. FY = units produced / capacity
A12: Units produced (tested) | B12: m units | C12: =C10*C11 -> 28 | D12: =D10*D11 -> 28 | E12: =E10*E11 -> 28 | F12: =F10*F11 -> 28 | G12: =G10*G11 -> 28 | H12: =H10*H11 -> 28 | I12: =I10*I11 -> 28 | J12: =J10*J11 -> 28 | ... N12: =N10*N11 -> 28 | O12: =SUM(C12:N12) -> 336 | P12: Calculated value (simulated inputs) | Q12: Capacity x utilization
A13: Manufacturing yield (final test) | B13: % | C13: =Assumptions!$C$64 -> 0.92 | D13: =Assumptions!$C$64 -> 0.92 | E13: =Assumptions!$C$64 -> 0.92 | F13: =Assumptions!$C$64 -> 0.92 | G13: =Assumptions!$C$64 -> 0.92 | H13: =Assumptions!$C$64 -> 0.92 | I13: =Assumptions!$C$64 -> 0.92 | J13: =Assumptions!$C$64 -> 0.92 | ... N13: =Assumptions!$C$64 -> 0.92 | O13: =IFERROR(O14/O12,0) -> 0.92 | P13: Calculated value (simulated inputs) | Q13: Scenario yield. FY = good units / units produced
A14: Good units produced | B14: m units | C14: =C12*C13 -> 25.76 | D14: =D12*D13 -> 25.76 | E14: =E12*E13 -> 25.76 | F14: =F12*F13 -> 25.76 | G14: =G12*G13 -> 25.76 | H14: =H12*H13 -> 25.76 | I14: =I12*I13 -> 25.76 | J14: =J12*J13 -> 25.76 | ... N14: =N12*N13 -> 25.76 | O14: =SUM(C14:N14) -> 309.12 | P14: Calculated value (simulated inputs) | Q14: Units produced x yield
A15: Opening finished-goods inventory | B15: m units | C15: =Assumptions!$C$67 -> 20.823167 | D15: =C18 -> 22.594879 | E15: =D18 -> 23.866835 | F15: =E18 -> 24.139279 | G15: =F18 -> 25.661113 | H15: =G18 -> 26.683191 | I15: =H18 -> 26.455879 | J15: =I18 -> 26.478445 | K15: =J18 -> 27.000767 | ... N15: =M18 -> 31.316391 | O15: =C15 -> 20.823167 | P15: Calculated value (simulated inputs) | Q15: First month: Assumptions opening balance; then prior month's closing
A16: Available good units | B16: m units | C16: =C15+C14 -> 46.583167 | D16: =D15+D14 -> 48.354879 | E16: =E15+E14 -> 49.626835 | F16: =F15+F14 -> 49.899279 | G16: =G15+G14 -> 51.421113 | H16: =H15+H14 -> 52.443191 | I16: =I15+I14 -> 52.215879 | J16: =J15+J14 -> 52.238445 | ... N16: =N15+N14 -> 57.076391 | P16: Calculated value (simulated inputs) | Q16: Opening inventory + good units produced
A17: Units sold | B17: m units | C17: =MIN(C9,C16) -> 23.988288 | D17: =MIN(D9,D16) -> 24.488044 | E17: =MIN(E9,E16) -> 25.487556 | F17: =MIN(F9,F16) -> 24.238166 | G17: =MIN(G9,G16) -> 24.737922 | H17: =MIN(H9,H16) -> 25.987312 | I17: =MIN(I9,I16) -> 25.737434 | J17: =MIN(J9,J16) -> 25.237678 | ... N17: =MIN(N9,N16) -> 26.986824 | O17: =SUM(C17:N17) -> 299.8536 | P17: Calculated value (simulated inputs) | Q17: MIN(customer demand, available good units)
A18: Closing finished-goods inventory | B18: m units | C18: =C16-C17 -> 22.594879 | D18: =D16-D17 -> 23.866835 | E18: =E16-E17 -> 24.139279 | F18: =F16-F17 -> 25.661113 | G18: =G16-G17 -> 26.683191 | H18: =H16-H17 -> 26.455879 | I18: =I16-I17 -> 26.478445 | J18: =J16-J17 -> 27.000767 | ... N18: =N16-N17 -> 30.089567 | O18: =N18 -> 30.089567 | P18: Calculated value (simulated inputs) | Q18: Available - units sold
A19: Unmet demand (supply shortfall) | B19: m units | C19: =C9-C17 -> 0 | D19: =D9-D17 -> 0 | E19: =E9-E17 -> 0 | F19: =F9-F17 -> 0 | G19: =G9-G17 -> 0 | H19: =H9-H17 -> 0 | I19: =I9-I17 -> 0 | J19: =J9-J17 -> 0 | ... N19: =N9-N17 -> 0 | O19: =SUM(C19:N19) -> 0 | P19: Calculated value (simulated inputs) | Q19: Demand - units sold. >0 means lost or delayed sales
A20: Demand / good-unit capacity (risk ratio) | B20: x | C20: =IFERROR(C9/(C10*C13),0) -> 0.74497789 | D20: =IFERROR(D9/(D10*D13),0) -> 0.76049826 | E20: =IFERROR(E9/(E10*E13),0) -> 0.79153901 | F20: =IFERROR(F9/(F10*F13),0) -> 0.75273807 | G20: =IFERROR(G9/(G10*G13),0) -> 0.76825845 | H20: =IFERROR(H9/(H10*H13),0) -> 0.80705938 | I20: =IFERROR(I9/(I10*I13),0) -> 0.79929919 | J20: =IFERROR(J9/(J10*J13),0) -> 0.78377882 | ... O20: =IFERROR(O9/(O10*O13),0) -> 0.77601863 | P20: Calculated value (simulated inputs) | Q20: Demand / (capacity x yield) = share of full-load good output needed. Feeds the risk heat map
A21: Average selling price | B21: $/unit | C21: =Assumptions!$C$63 -> 1.98 | D21: =Assumptions!$C$63 -> 1.98 | E21: =Assumptions!$C$63 -> 1.98 | F21: =Assumptions!$C$63 -> 1.98 | G21: =Assumptions!$C$63 -> 1.98 | H21: =Assumptions!$C$63 -> 1.98 | I21: =Assumptions!$C$63 -> 1.98 | J21: =Assumptions!$C$63 -> 1.98 | ... N21: =Assumptions!$C$63 -> 1.98 | O21: =IFERROR(O22/O17,0) -> 1.98 | P21: Calculated value (simulated inputs) | Q21: Scenario ASP. FY = revenue / units sold
A22: Revenue | B22: $m | C22: =C17*C21 -> 47.49681 | D22: =D17*D21 -> 48.486327 | E22: =E17*E21 -> 50.465361 | F22: =F17*F21 -> 47.991569 | G22: =G17*G21 -> 48.981085 | H22: =H17*H21 -> 51.454878 | I22: =I17*I21 -> 50.960119 | J22: =J17*J21 -> 49.970602 | ... N22: =N17*N21 -> 53.433911 | O22: =SUM(C22:N22) -> 593.71013 | P22: Calculated value (simulated inputs) | Q22: Units sold x ASP
A23: Variable cost per unit produced | B23: $/unit | C23: =Assumptions!$C$66 -> 0.3193 | D23: =Assumptions!$C$66 -> 0.3193 | E23: =Assumptions!$C$66 -> 0.3193 | F23: =Assumptions!$C$66 -> 0.3193 | G23: =Assumptions!$C$66 -> 0.3193 | H23: =Assumptions!$C$66 -> 0.3193 | I23: =Assumptions!$C$66 -> 0.3193 | J23: =Assumptions!$C$66 -> 0.3193 | ... N23: =Assumptions!$C$66 -> 0.3193 | O23: =IFERROR(O24/O12,0) -> 0.3193 | P23: Calculated value (simulated inputs) | Q23: Scenario variable cost per unit
A24: Variable manufacturing cost | B24: $m | C24: =C12*C23 -> 8.9404 | D24: =D12*D23 -> 8.9404 | E24: =E12*E23 -> 8.9404 | F24: =F12*F23 -> 8.9404 | G24: =G12*G23 -> 8.9404 | H24: =H12*H23 -> 8.9404 | I24: =I12*I23 -> 8.9404 | J24: =J12*J23 -> 8.9404 | ... N24: =N12*N23 -> 8.9404 | O24: =SUM(C24:N24) -> 107.2848 | P24: Calculated value (simulated inputs) | Q24: Units produced x variable cost per unit
A25: Fixed manufacturing cost | B25: $m | C25: =Assumptions!$C$45 -> 9.5 | D25: =Assumptions!$C$45 -> 9.5 | E25: =Assumptions!$C$45 -> 9.5 | F25: =Assumptions!$C$45 -> 9.5 | G25: =Assumptions!$C$45 -> 9.5 | H25: =Assumptions!$C$45 -> 9.5 | I25: =Assumptions!$C$45 -> 9.5 | J25: =Assumptions!$C$45 -> 9.5 | ... N25: =Assumptions!$C$45 -> 9.5 | O25: =SUM(C25:N25) -> 114 | P25: Calculated value (simulated inputs) | Q25: Monthly fixed cost (Assumptions D)
A26: Total manufacturing cost | B26: $m | C26: =C24+C25 -> 18.4404 | D26: =D24+D25 -> 18.4404 | E26: =E24+E25 -> 18.4404 | F26: =F24+F25 -> 18.4404 | G26: =G24+G25 -> 18.4404 | H26: =H24+H25 -> 18.4404 | I26: =I24+I25 -> 18.4404 | J26: =J24+J25 -> 18.4404 | ... N26: =N24+N25 -> 18.4404 | O26: =SUM(C26:N26) -> 221.2848 | P26: Calculated value (simulated inputs) | Q26: Variable + fixed manufacturing cost
A27: Cost per good unit | B27: $/unit | C27: =IFERROR(C26/C14,0) -> 0.71585404 | D27: =IFERROR(D26/D14,0) -> 0.71585404 | E27: =IFERROR(E26/E14,0) -> 0.71585404 | F27: =IFERROR(F26/F14,0) -> 0.71585404 | G27: =IFERROR(G26/G14,0) -> 0.71585404 | H27: =IFERROR(H26/H14,0) -> 0.71585404 | I27: =IFERROR(I26/I14,0) -> 0.71585404 | J27: =IFERROR(J26/J14,0) -> 0.71585404 | ... O27: =IFERROR(O26/O14,0) -> 0.71585404 | P27: Calculated value (simulated inputs) | Q27: Total manufacturing cost / good units. Rises when yield or utilization falls
A28: Opening inventory value | B28: $m | C28: =Assumptions!$C$68 -> 16.516502 | D28: =C31 -> 16.95563 | E28: =D31 -> 17.470651 | F28: =E31 -> 17.467704 | G28: =F31 -> 18.466037 | H28: =G31 -> 19.151307 | I28: =H31 -> 18.96379 | J28: =I31 -> 18.967502 | K28: =J31 -> 19.335224 | ... N28: =M31 -> 22.419094 | O28: =C28 -> 16.516502 | P28: Calculated value (simulated inputs) | Q28: Prior month's closing value
A29: Average cost per available unit | B29: $/unit | C29: =IFERROR((C28+C26)/C16,0) -> 0.75041918 | D29: =IFERROR((D28+D26)/D16,0) -> 0.73200536 | E29: =IFERROR((E28+E26)/E16,0) -> 0.72362163 | F29: =IFERROR((F28+F26)/F16,0) -> 0.71961169 | G29: =IFERROR((G28+G26)/G16,0) -> 0.71772925 | H29: =IFERROR((H28+H26)/H16,0) -> 0.71680815 | I29: =IFERROR((I28+I26)/I16,0) -> 0.71633745 | J29: =IFERROR((J28+J26)/J16,0) -> 0.71609907 | ... N29: =IFERROR((N28+N26)/N16,0) -> 0.71587381 | P29: Calculated value (simulated inputs) | Q29: (Opening value + manufacturing cost) / available units - weighted-average costing
A30: Cost of revenue | B30: $m | C30: =C17*C29 -> 18.001271 | D30: =D17*D29 -> 17.925379 | E30: =E17*E29 -> 18.443347 | F30: =F17*F29 -> 17.442068 | G30: =G17*G29 -> 17.75513 | H30: =H17*H29 -> 18.627917 | I30: =I17*I29 -> 18.436688 | J30: =J17*J29 -> 18.072678 | ... N30: =N17*N29 -> 19.319161 | O30: =SUM(C30:N30) -> 216.26097 | P30: Calculated value (simulated inputs) | Q30: Units sold x average cost
A31: Closing inventory value | B31: $m | C31: =C28+C26-C30 -> 16.95563 | D31: =D28+D26-D30 -> 17.470651 | E31: =E28+E26-E30 -> 17.467704 | F31: =F28+F26-F30 -> 18.466037 | G31: =G28+G26-G30 -> 19.151307 | H31: =H28+H26-H30 -> 18.96379 | I31: =I28+I26-I30 -> 18.967502 | J31: =J28+J26-J30 -> 19.335224 | ... N31: =N28+N26-N30 -> 21.540333 | O31: =N31 -> 21.540333 | P31: Calculated value (simulated inputs) | Q31: Opening value + manufacturing cost - cost of revenue
A32: Contribution margin | B32: $m | C32: =C22-C17*IFERROR(C23/C13,0) -> 39.17131 | D32: =D22-D17*IFERROR(D23/D13,0) -> 39.987379 | E32: =E22-E17*IFERROR(E23/E13,0) -> 41.619517 | F32: =F22-F17*IFERROR(F23/F13,0) -> 39.579344 | G32: =G22-G17*IFERROR(G23/G13,0) -> 40.395413 | H32: =H22-H17*IFERROR(H23/H13,0) -> 42.435586 | I32: =I22-I17*IFERROR(I23/I13,0) -> 42.027551 | J32: =J22-J17*IFERROR(J23/J13,0) -> 41.211482 | ... N32: =N22-N17*IFERROR(N23/N13,0) -> 44.067724 | O32: =SUM(C32:N32) -> 489.64137 | P32: Calculated value (simulated inputs) | Q32: Revenue - units sold x variable cost per good unit (variable cost / yield)
A33: Contribution margin % | B33: % | C33: =IFERROR(C32/C22,0) -> 0.82471454 | D33: =IFERROR(D32/D22,0) -> 0.82471454 | E33: =IFERROR(E32/E22,0) -> 0.82471454 | F33: =IFERROR(F32/F22,0) -> 0.82471454 | G33: =IFERROR(G32/G22,0) -> 0.82471454 | H33: =IFERROR(H32/H22,0) -> 0.82471454 | I33: =IFERROR(I32/I22,0) -> 0.82471454 | J33: =IFERROR(J32/J22,0) -> 0.82471454 | ... O33: =IFERROR(O32/O22,0) -> 0.82471454 | P33: Calculated value (simulated inputs) | Q33: Contribution margin / revenue
A34: Gross profit | B34: $m | C34: =C22-C30 -> 29.495539 | D34: =D22-D30 -> 30.560948 | E34: =E22-E30 -> 32.022014 | F34: =F22-F30 -> 30.549501 | G34: =G22-G30 -> 31.225955 | H34: =H22-H30 -> 32.826961 | I34: =I22-I30 -> 32.523431 | J34: =J22-J30 -> 31.897925 | ... N34: =N22-N30 -> 34.114751 | O34: =SUM(C34:N34) -> 377.44916 | P34: Calculated value (simulated inputs) | Q34: Revenue - cost of revenue
A35: Gross margin % | B35: % | C35: =IFERROR(C34/C22,0) -> 0.62100041 | D35: =IFERROR(D34/D22,0) -> 0.63030032 | E35: =IFERROR(E34/E22,0) -> 0.63453453 | F35: =IFERROR(F34/F22,0) -> 0.63655975 | G35: =IFERROR(G34/G22,0) -> 0.63751048 | H35: =IFERROR(H34/H22,0) -> 0.63797568 | I35: =IFERROR(I34/I22,0) -> 0.63821341 | J35: =IFERROR(J34/J22,0) -> 0.6383338 | ... O35: =IFERROR(O34/O22,0) -> 0.63574654 | P35: Calculated value (simulated inputs) | Q35: Gross profit / revenue
A37: Analog & power management - Simulated data created for portfolio demonstration. It does not represent nonpublic Microchip Technology information.
A38: Seasonality factor | B38: x | C38: =Assumptions!C$72 -> 0.96 | D38: =Assumptions!D$72 -> 0.98 | E38: =Assumptions!E$72 -> 1.02 | F38: =Assumptions!F$72 -> 0.97 | G38: =Assumptions!G$72 -> 0.99 | H38: =Assumptions!H$72 -> 1.04 | I38: =Assumptions!I$72 -> 1.03 | J38: =Assumptions!J$72 -> 1.01 | ... N38: =Assumptions!N$72 -> 1.08 | O38: =SUM(C38:N38) -> 12 | P38: Calculated value (simulated inputs) | Q38: Link: Assumptions section E
A39: Customer demand | B39: m units | C39: =Assumptions!$D$62*C38/12 -> 32.427702 | D39: =Assumptions!$D$62*D38/12 -> 33.103279 | E39: =Assumptions!$D$62*E38/12 -> 34.454433 | F39: =Assumptions!$D$62*F38/12 -> 32.76549 | G39: =Assumptions!$D$62*G38/12 -> 33.441067 | H39: =Assumptions!$D$62*H38/12 -> 35.13001 | I39: =Assumptions!$D$62*I38/12 -> 34.792221 | J39: =Assumptions!$D$62*J38/12 -> 34.116644 | ... N39: =Assumptions!$D$62*N38/12 -> 36.481164 | O39: =SUM(C39:N39) -> 405.34627 | P39: Calculated value (simulated inputs) | Q39: FY2027 demand x seasonality / 12
A40: Internal final-test capacity | B40: m units | C40: =Assumptions!$D$46 -> 46 | D40: =Assumptions!$D$46 -> 46 | E40: =Assumptions!$D$46 -> 46 | F40: =Assumptions!$D$46 -> 46 | G40: =Assumptions!$D$46 -> 46 | H40: =Assumptions!$D$46 -> 46 | I40: =Assumptions!$D$46 -> 46 | J40: =Assumptions!$D$46 -> 46 | ... N40: =Assumptions!$D$46 -> 46 | O40: =SUM(C40:N40) -> 552 | P40: Calculated value (simulated inputs) | Q40: Monthly capacity (Assumptions D)
A41: Capacity utilization | B41: % | C41: =Assumptions!$D$65 -> 0.8 | D41: =Assumptions!$D$65 -> 0.8 | E41: =Assumptions!$D$65 -> 0.8 | F41: =Assumptions!$D$65 -> 0.8 | G41: =Assumptions!$D$65 -> 0.8 | H41: =Assumptions!$D$65 -> 0.8 | I41: =Assumptions!$D$65 -> 0.8 | J41: =Assumptions!$D$65 -> 0.8 | ... N41: =Assumptions!$D$65 -> 0.8 | O41: =IFERROR(O42/O40,0) -> 0.8 | P41: Calculated value (simulated inputs) | Q41: Scenario utilization. FY = units produced / capacity
A42: Units produced (tested) | B42: m units | C42: =C40*C41 -> 36.8 | D42: =D40*D41 -> 36.8 | E42: =E40*E41 -> 36.8 | F42: =F40*F41 -> 36.8 | G42: =G40*G41 -> 36.8 | H42: =H40*H41 -> 36.8 | I42: =I40*I41 -> 36.8 | J42: =J40*J41 -> 36.8 | ... N42: =N40*N41 -> 36.8 | O42: =SUM(C42:N42) -> 441.6 | P42: Calculated value (simulated inputs) | Q42: Capacity x utilization
...

Sheet Revenue
A1: Monthly Revenue Forecast - FY2027 (active scenario)
A2: Revenue by product line, units in millions, $m. Simulated data created for portfolio demonstration. It does not represent nonpublic Microchip Technology information.
A3: Simulated data created for portfolio demonstration. It does not represent nonpublic Microchip Technology information.
A4: Scenario shown: | B4: =Assumptions!$C$6 -> Base
A6: Line item | B6: Units | C6: =Ops_Model!C$6 -> 46113 | D6: =Ops_Model!D$6 -> 46143 | E6: =Ops_Model!E$6 -> 46174 | F6: =Ops_Model!F$6 -> 46204 | G6: =Ops_Model!G$6 -> 46235 | H6: =Ops_Model!H$6 -> 46266 | I6: =Ops_Model!I$6 -> 46296 | J6: =Ops_Model!J$6 -> 46327 | ... N6: =Ops_Model!N$6 -> 46447 | O6: FY2027 | P6: Q1 FY27 | Q6: Q2 FY27 | R6: Q3 FY27 | S6: Q4 FY27 | T6: FY2026 base | U6: FY27 vs FY26 | V6: Classification | W6: Formula
A7: Mixed-signal microcontrollers
A8: Units sold | B8: m units | C8: =Ops_Model!C$17 -> 23.988288 | D8: =Ops_Model!D$17 -> 24.488044 | E8: =Ops_Model!E$17 -> 25.487556 | F8: =Ops_Model!F$17 -> 24.238166 | G8: =Ops_Model!G$17 -> 24.737922 | H8: =Ops_Model!H$17 -> 25.987312 | I8: =Ops_Model!I$17 -> 25.737434 | J8: =Ops_Model!J$17 -> 25.237678 | ... N8: =Ops_Model!N$17 -> 26.986824 | O8: =SUM(C8:N8) -> 299.8536 | P8: =SUM(C8:E8) -> 73.963888 | Q8: =SUM(F8:H8) -> 74.9634 | R8: =SUM(I8:K8) -> 74.713522 | S8: =SUM(L8:N8) -> 76.21279 | T8: =Assumptions!C$51 -> 249.878 | U8: =IFERROR(O8/T8-1,"") -> 0.2 | V8: Calculated value (simulated inputs) | W8: Link: Ops_Model units sold
A9: Revenue | B9: $m | C9: =Ops_Model!C$22 -> 47.49681 | D9: =Ops_Model!D$22 -> 48.486327 | E9: =Ops_Model!E$22 -> 50.465361 | F9: =Ops_Model!F$22 -> 47.991569 | G9: =Ops_Model!G$22 -> 48.981085 | H9: =Ops_Model!H$22 -> 51.454878 | I9: =Ops_Model!I$22 -> 50.960119 | J9: =Ops_Model!J$22 -> 49.970602 | ... N9: =Ops_Model!N$22 -> 53.433911 | O9: =SUM(C9:N9) -> 593.71013 | P9: =SUM(C9:E9) -> 146.4485 | Q9: =SUM(F9:H9) -> 148.42753 | R9: =SUM(I9:K9) -> 147.93277 | S9: =SUM(L9:N9) -> 150.90132 | T9: =Assumptions!C$41 -> 499.756 | U9: =IFERROR(O9/T9-1,"") -> 0.188 | V9: Calculated value (simulated inputs) | W9: Link: Ops_Model revenue
A10: Average selling price | B10: $/unit | C10: =IFERROR(C9/C8,0) -> 1.98 | D10: =IFERROR(D9/D8,0) -> 1.98 | E10: =IFERROR(E9/E8,0) -> 1.98 | F10: =IFERROR(F9/F8,0) -> 1.98 | G10: =IFERROR(G9/G8,0) -> 1.98 | H10: =IFERROR(H9/H8,0) -> 1.98 | I10: =IFERROR(I9/I8,0) -> 1.98 | J10: =IFERROR(J9/J8,0) -> 1.98 | ... T10: =IFERROR(T9/T8,0) -> 2 | V10: Calculated value (simulated inputs) | W10: Revenue / units sold
A12: Analog & power management
A13: Units sold | B13: m units | C13: =Ops_Model!C$47 -> 32.427702 | D13: =Ops_Model!D$47 -> 33.103279 | E13: =Ops_Model!E$47 -> 34.454433 | F13: =Ops_Model!F$47 -> 32.76549 | G13: =Ops_Model!G$47 -> 33.441067 | H13: =Ops_Model!H$47 -> 35.13001 | I13: =Ops_Model!I$47 -> 34.792221 | J13: =Ops_Model!J$47 -> 34.116644 | ... N13: =Ops_Model!N$47 -> 36.481164 | O13: =SUM(C13:N13) -> 405.34627 | P13: =SUM(C13:E13) -> 99.985413 | Q13: =SUM(F13:H13) -> 101.33657 | R13: =SUM(I13:K13) -> 100.99878 | S13: =SUM(L13:N13) -> 103.02551 | T13: =Assumptions!D$51 -> 352.47502 | U13: =IFERROR(O13/T13-1,"") -> 0.15 | V13: Calculated value (simulated inputs) | W13: Link: Ops_Model units sold
A14: Revenue | B14: $m | C14: =Ops_Model!C$52 -> 25.68274 | D14: =Ops_Model!D$52 -> 26.217797 | E14: =Ops_Model!E$52 -> 27.287911 | F14: =Ops_Model!F$52 -> 25.950268 | G14: =Ops_Model!G$52 -> 26.485325 | H14: =Ops_Model!H$52 -> 27.822968 | I14: =Ops_Model!I$52 -> 27.555439 | J14: =Ops_Model!J$52 -> 27.020382 | ... N14: =Ops_Model!N$52 -> 28.893082 | O14: =SUM(C14:N14) -> 321.03424 | P14: =SUM(C14:E14) -> 79.188447 | Q14: =SUM(F14:H14) -> 80.258561 | R14: =SUM(I14:K14) -> 79.991033 | S14: =SUM(L14:N14) -> 81.596204 | T14: =Assumptions!D$41 -> 281.98001 | U14: =IFERROR(O14/T14-1,"") -> 0.1385 | V14: Calculated value (simulated inputs) | W14: Link: Ops_Model revenue
A15: Average selling price | B15: $/unit | C15: =IFERROR(C14/C13,0) -> 0.792 | D15: =IFERROR(D14/D13,0) -> 0.792 | E15: =IFERROR(E14/E13,0) -> 0.792 | F15: =IFERROR(F14/F13,0) -> 0.792 | G15: =IFERROR(G14/G13,0) -> 0.792 | H15: =IFERROR(H14/H13,0) -> 0.792 | I15: =IFERROR(I14/I13,0) -> 0.792 | J15: =IFERROR(J14/J13,0) -> 0.792 | ... T15: =IFERROR(T14/T13,0) -> 0.8 | V15: Calculated value (simulated inputs) | W15: Revenue / units sold
A17: FPGAs
A18: Units sold | B18: m units | C18: =Ops_Model!C$77 -> 0.87305595 | D18: =Ops_Model!D$77 -> 0.89124462 | E18: =Ops_Model!E$77 -> 0.92762195 | F18: =Ops_Model!F$77 -> 0.88215028 | G18: =Ops_Model!G$77 -> 0.90033895 | H18: =Ops_Model!H$77 -> 0.94581061 | I18: =Ops_Model!I$77 -> 0.93671628 | J18: =Ops_Model!J$77 -> 0.91852761 | ... N18: =Ops_Model!N$77 -> 0.98218794 | O18: =SUM(C18:N18) -> 10.913199 | P18: =SUM(C18:E18) -> 2.6919225 | Q18: =SUM(F18:H18) -> 2.7282998 | R18: =SUM(I18:K18) -> 2.7192055 | S18: =SUM(L18:N18) -> 2.7737715 | T18: =Assumptions!E$51 -> 8.7305595 | U18: =IFERROR(O18/T18-1,"") -> 0.25 | V18: Calculated value (simulated inputs) | W18: Link: Ops_Model units sold
A19: Revenue | B19: $m | C19: =Ops_Model!C$82 -> 21.608135 | D19: =Ops_Model!D$82 -> 22.058304 | E19: =Ops_Model!E$82 -> 22.958643 | F19: =Ops_Model!F$82 -> 21.83322 | G19: =Ops_Model!G$82 -> 22.283389 | H19: =Ops_Model!H$82 -> 23.408813 | I19: =Ops_Model!I$82 -> 23.183728 | J19: =Ops_Model!J$82 -> 22.733558 | ... N19: =Ops_Model!N$82 -> 24.309152 | O19: =SUM(C19:N19) -> 270.10168 | P19: =SUM(C19:E19) -> 66.625082 | Q19: =SUM(F19:H19) -> 67.525421 | R19: =SUM(I19:K19) -> 67.300336 | S19: =SUM(L19:N19) -> 68.650845 | T19: =Assumptions!E$41 -> 218.26399 | U19: =IFERROR(O19/T19-1,"") -> 0.2375 | V19: Calculated value (simulated inputs) | W19: Link: Ops_Model revenue
