Workbook

Sheet Cover
B2: Semiconductor FP&A Forecasting and Decision Model
B3: Fictional Power, Signal & Embedded Division, modeled on Texas Instruments Incorporated (NASDAQ: TXN)
B5: Simulated data created for portfolio demonstration. It does not represent nonpublic Texas Instruments information.
B6: Reported public data comes only from Texas Instruments's SEC filings (see Sources_Log). All division-level operating data is simulated and labeled as such.
B8: Business question | C8: How would changes in demand, average selling price, product mix, manufacturing yield, capacity utilization, operating costs and capital spending affect the division's revenue, operating profit and free cash flow?
B10: Model status | C10: =Checks!$C$172 -> ALL CHECKS PASS
B11: Built by | C11: scripts/build_model.py --company TXN (config: companies/TXN/config.toml)
B13: Tab guide
B14: Cover | C14: This page
B15: Sources_Log | C15: Source register (SEC filings) and assumptions log
B16: Assumptions | C16: Scenario selector (one cell), 9 scenario drivers, division & product inputs, seasonality
B17: Hist_Data | C17: Reported financials FY2021-FY2025, one source per row (inputs)
B18: Hist_Analysis | C18: Growth, margins, segment mix, free cash flow, working capital (formulas)
B19: Ops_Model | C19: Product x month operating model: demand, capacity, yield, inventory, revenue, cost, gross profit
B20: Revenue | C20: Monthly revenue forecast by product line, mix, quarters, FY vs FY2025 base year
B21: PnL | C21: Monthly P&L to net income; EBITDA; FY2025 base-year comparison
B22: FCF | C22: Capex and depreciation, working capital, free cash flow
B23: Budget | C23: FY2026 budget = Base scenario, locked (does not follow the selector)
B24: Actuals | C24: SIMULATED actual results Jan-May 2026, same operating logic
B25: Variance | C25: YTD budget vs actual: price/volume/mix, operating-profit bridge, reconciliation flags
... B28: Checks | C28: Independent checks and hand-calculable unit tests; overall status feeds this cover
B30: Color legend
B31: 1,234.5 | C31: Blue: hardcoded input (reported value or assumption)
B32: 1,234.5 | C32: Black: formula / calculation
B33: 1,234.5 | C33: Green: direct link to another tab
B34: Input | C34: Yellow fill: key assumption / cell a user may change
B36: Value classification
C37: Reported public data - transcribed from an SEC filing (source on every row)
C38: Calculated value - Excel formula on other cells
C39: User-provided assumption - logged in Sources_Log with who decided it
C40: Simulated operational data - labeled with the disclaimer above
B42: Units & conventions | C42: USD millions unless noted. Fiscal year ends December 31. Negatives in parentheses. Capex printed negative in Hist_Data, positive in analysis.

Sheet Sources_Log
A1: Source Register and Assumptions Log
A2: Every reported value traces to a source below. Every assumption is logged with who decided it.
A3: Simulated data created for portfolio demonstration. It does not represent nonpublic Texas Instruments information.
A5: Source register
A6: ID | B6: Document | C6: Accession no. | D6: Period covered | E6: URL | F6: Used for | G6: Accessed
A7: S-001 | B7: Form 10-K fiscal 2025 | C7: 0000097476-26-000059 | D7: FY2023-FY2025 income statement & cash flow; FY2024-FY2025 balance sheet; segment revenue and gross profit FY2023-FY2025 | E7: https://www.sec.gov/Archives/edgar/data/97476/000009747626000059/ | F7: Historical analysis; product-mix anchor | G7: 2026-09-22
A8: S-002 | B8: Form 10-K fiscal 2023 | C8: 0000097476-24-000007 | D8: FY2021-FY2022 income statement & cash flow; FY2022-FY2023 balance sheet; FY2021-FY2022 segment revenue | E8: https://www.sec.gov/Archives/edgar/data/97476/000009747624000007/ | F8: Historical analysis; cross-filing check | G8: 2026-09-22
A9: S-003 | B9: Form 10-K fiscal 2022 | C9: 0000097476-23-000007 | D9: FY2021 balance sheet | E9: https://www.sec.gov/Archives/edgar/data/97476/000009747623000007/ | F9: Historical analysis; cross-filing check | G9: 2026-09-22
A10: S-004 | B10: Form 10-K fiscal 2024 | C10: 0000097476-25-000007 | D10: FY2023-FY2024 balance sheet (second transcription) | E10: https://www.sec.gov/Archives/edgar/data/97476/000009747625000007/ | F10: Cross-filing check only | G10: 2026-09-22
A11: S-005 | B11: Form 10-Q second quarter 2026 | C11: 0000097476-26-000152 | D11: Three months ended June 30 2026 and 2025: income statement and segment revenue | E11: https://www.sec.gov/Archives/edgar/data/97476/000009747626000152/ | F11: Quarterly context for the demand-growth assumption | G11: 2026-09-22
A13: Assumptions log
A14: ID | B14: Area | C14: Assumption | D14: Value | E14: Rationale | F14: Classification | G14: Decided by | H14: Status
A15: A-001 | B15: Scope | C15: Public company used for historical data | D15: Texas Instruments Incorporated (NASDAQ: TXN) | E15: Second test company for the multi-company engine (Phase 10c) | F15: User-provided assumption | G15: User | H15: Final
A16: A-002 | B16: Scope | C16: Historical window | D16: FY2021-FY2025 (fiscal year = calendar year) | E16: Five reported years (engine layout); covers the 2022 peak and the 2024 trough | F16: User-provided assumption | G16: Claude (delegated by user) | H16: Final
A17: A-003 | B17: Timing | C17: Forecast period | D17: FY2026 monthly: Jan-2026 to Dec-2026 | E17: TI's current fiscal year | F17: User-provided assumption | G17: Claude (delegated by user) | H17: Final
A18: A-004 | B18: Timing | C18: Actuals vs forecast split | D18: Jan-May 2026 = simulated actuals; Jun-Dec = forecast | E18: The engine layout uses exactly five actual months; as of September this is conservative (June-August not loaded) | F18: User-provided assumption | G18: Claude (delegated by user) | H18: Final
A19: A-005 | B19: Division | C19: Fictional division | D19: "Power, Signal & Embedded Division" - fictional, modeled on TI | E19: Matches the three product categories in the project brief | F19: User-provided assumption | G19: Claude (delegated by user) | H19: Final
A20: A-006 | B20: Division | C20: Division base-year (FY2025) revenue | D20: $1000.0M | E20: Same scale as the Microchip build for comparability | F20: User-provided assumption | G20: Claude (delegated by user) | H20: Final
A21: A-007 | B21: Division | C21: Product categories and mapping | D21: 1) Power-management chips 2) Signal-chain chips 3) Embedded processors; power and signal = assumed split of TI's Analog segment; embedded = TI's Embedded Processing segment | E21: User chose option B (follow the brief) over option A (TI's own segments) | F21: User-provided assumption | G21: User | H21: Final
A22: A-008 | B22: Division | C22: Split of TI's Analog segment | D22: Power 50% / Signal chain 50% | E22: TI does not report power and signal chain separately; 50/50 is a neutral placeholder - replace if a sourced split is available | F22: User-provided assumption | G22: Claude (delegated by user) | H22: Open - user may change
A23: A-009 | B23: Division | C23: Segments not modeled | D23: TI Other segment (5.5% of FY2025 revenue) excluded; three-product mix renormalized to 100% | E23: The brief names three product categories only | F23: User-provided assumption | G23: Claude (delegated by user) | H23: Final
A24: A-010 | B24: Labeling | C24: Simulated-data disclaimer | D24: Simulated data created for portfolio demonstration. It does not represent nonpublic Texas Instruments information. | E24: Project rule | F24: User-provided assumption | G24: User | H24: Final
A25: A-011 | B25: Operations | C25: Base-year product inputs | D25: ASP $0.60 / $0.95 / $3.40; yield 95% / 93% / 88%; variable cost $0.14 / $0.21 / $0.95; fixed $5.8m / $6.2m / $2.5m per month; capacity 88 / 60 / 7 m units per month | E25: Calibrated so base-year division gross margin (57.2%) is close to TI's reported FY2025 gross margin (57.0%) | F25: Simulated operational data | G25: Claude (delegated by user) | H25: Final
... A38: A-024 | B38: Data | C38: Sign convention for interest and restructuring | D38: Interest and debt expense stored negative; restructuring credit (2024) stored negative | E38: So pre-tax income = operating profit + non-operating items holds; noted on each row | F38: User-provided assumption | G38: Claude (delegated by user) | H38: Final

Sheet Assumptions
A1: Assumptions and Scenario Controls
A2: Change ONLY the yellow selector (C6) to switch scenario. Blue = input. Every forecast tab reads the Live column.
A3: Simulated data created for portfolio demonstration. It does not represent nonpublic Texas Instruments information.
A6: ACTIVE SCENARIO (choose Downside / Base / Upside) | C6: Base | D6: =MATCH($C$6,$C$9:$E$9,0) -> 2 | E6: <- scenario index (1 = Downside, 2 = Base, 3 = Upside)
A8: A. Scenario drivers (FY2026 vs FY2025 base year)
A9: Driver | B9: Units | C9: Downside | D9: Base | E9: Upside | F9: LIVE | P9: Classification | Q9: Rationale / reference
A10: Customer demand growth | B10: % | C10: 0.03 | D10: 0.15 | E10: 0.24 | F10: =INDEX(C10:E10,1,$D$6) -> 0.15 | P10: User-provided assumption | Q10: TI Q2 FY2026 revenue +22.8% YoY (section B). Base takes a more cautious +15% for the full year.
A11: Average selling price change | B11: % | C11: -0.03 | D11: -0.01 | E11: 0.01 | F11: =INDEX(C11:E11,1,$D$6) -> -0.01 | P11: User-provided assumption | Q11: Mature analog prices drift down slowly; downside = price competition.
A12: Manufacturing yield change (percentage points vs base-year yield) | B12: pts | C12: -0.02 | D12: 0 | E12: 0.01 | F12: =INDEX(C12:E12,1,$D$6) -> 0 | P12: User-provided assumption | Q12: Applied to each product's base-year final-test yield (section D).
A13: Capacity utilization (internal final test) | B13: % | C13: 0.68 | D13: 0.78 | E13: 0.86 | F13: =INDEX(C13:E13,1,$D$6) -> 0.78 | P13: User-provided assumption | Q13: Assumed. TI does not disclose utilization; implied base-year loading is shown in section D.
A14: Material-cost inflation (variable cost per unit) | B14: % | C14: 0.05 | D14: 0.03 | E14: 0.01 | F14: =INDEX(C14:E14,1,$D$6) -> 0.03 | P14: User-provided assumption | Q14: Wafer, substrate and packaging cost inflation.
A15: R&D expense growth | B15: % | C15: 0.02 | D15: 0.05 | E15: 0.08 | F15: =INDEX(C15:E15,1,$D$6) -> 0.05 | P15: User-provided assumption | Q15: TI R&D grew +6.3% in FY2025 (section B).
A16: SG&A expense growth | B16: % | C16: 0.01 | D16: 0.03 | E16: 0.05 | F16: =INDEX(C16:E16,1,$D$6) -> 0.03 | P16: User-provided assumption | Q16: TI SG&A grew +3.7% in FY2025 (section B).
A17: Capital expenditures (% of revenue, excl. proposed test-equipment project) | B17: % | C17: 0.04 | D17: 0.05 | E17: 0.06 | F17: =INDEX(C17:E17,1,$D$6) -> 0.05 | P17: User-provided assumption | Q17: TI capex was 25.7% of revenue in FY2025 (section B), driven by its corporate 300-mm fab build-out; division equipment capex assumed far lower.
A18: Tax rate | B18: % | C18: 0.16 | D18: 0.13 | E18: 0.12 | F18: =INDEX(C18:E18,1,$D$6) -> 0.13 | P18: User-provided assumption | Q18: TI effective rate about 12-13% in FY2021-FY2025 (section B). Downside = higher rate.
A20: B. Reference points from Texas Instruments's reported history (formulas - context for the drivers above)
A21: Q2 FY2026 net sales growth vs Q2 FY2025 | F21: =Hist_Analysis!$E$51 -> 0.22819245 | P21: Calculated value | Q21: Reported public data (Hist tabs)
A22: Q2 FY2026 sales x 4 vs FY2025 net sales | F22: =Hist_Data!$D$68*4/Hist_Data!$G$7-1 -> 0.23583305 | P22: Calculated value | Q22: Reported public data (Hist tabs)
A23: Gross margin FY2025 (reported basis) | F23: =Hist_Analysis!$G$9 -> 0.57024092 | P23: Calculated value | Q23: Reported public data (Hist tabs)
A24: Gross margin FY2022 (highest in the history) | F24: =Hist_Analysis!$D$9 -> 0.68758738 | P24: Calculated value | Q24: Reported public data (Hist tabs)
A25: R&D growth FY2025 | F25: =Hist_Data!$G$10/Hist_Data!$F$10-1 -> 0.063297601 | P25: Calculated value | Q25: Reported public data (Hist tabs)
A26: SG&A growth FY2025 | F26: =Hist_Data!$G$11/Hist_Data!$F$11-1 -> 0.036789298 | P26: Calculated value | Q26: Reported public data (Hist tabs)
A27: Capex % of sales FY2025 | F27: =Hist_Analysis!$G$37 -> 0.25732383 | P27: Calculated value | Q27: Reported public data (Hist tabs)
A28: Capex % of sales, average FY2021-FY2025 | F28: =AVERAGE(Hist_Analysis!$C$37:$G$37) -> 0.22576255 | P28: Calculated value | Q28: Reported public data (Hist tabs)
A29: Effective tax rate, average FY2021-FY2025 (years shown n.m. excluded) | F29: =AVERAGE(Hist_Analysis!$C$17:$G$17) -> 0.12466721 | P29: Calculated value | Q29: Reported public data (Hist tabs)
A31: C. Fictional Power, Signal & Embedded Division - base year FY2025 (Simulated data created for portfolio demonstration. It does not represent nonpublic Texas Instruments information.)
A32: Division net revenue, FY2025 base year | B32: $m | F32: 1000 | P32: User-provided assumption | Q32: User-provided assumption. ~6% of Texas Instruments FY2025 net sales
A33: Division R&D expense, FY2025 base year | B33: $m | F33: 120 | P33: Simulated operational data | Q33: 12% of revenue. TI company-wide R&D was 11.8% of revenue in FY2025. Used in Phase 3.
A34: Division SG&A expense, FY2025 base year | B34: $m | F34: 100 | P34: Simulated operational data | Q34: 10% of revenue. TI company-wide SG&A was 10.5% of revenue in FY2025. Used in Phase 3.
A35: Forecast start month (first month of FY2026) | F35: 46023 | P35: User-provided assumption | Q35: FY2026 = Jan-2026 to Dec-2026, calendar months
A37: D. Product inputs - base year FY2025 (simulated) and live FY2026 drivers (calculated)
A38: Input | B38: Units | C38: Power management | D38: Signal chain | E38: Embedded processors | F38: Division | P38: Classification | Q38: Notes
A39: Share of the reported segment assigned to this product | B39: % | C39: 0.5 | D39: 0.5 | E39: 1 | P39: User-provided assumption | Q39: User-provided assumption (option B). TI does not report power and signal chain separately; 50/50 is a neutral split. Change it in companies/TXN/config.toml.
A40: Reported segment share of net sales x assigned share | B40: % | C40: =Hist_Analysis!$G$20*$C$39 -> 0.39605248 | D40: =Hist_Analysis!$G$20*$D$39 -> 0.39605248 | E40: =Hist_Analysis!$G$21*$E$39 -> 0.15252799 | F40: =SUM(C40:E40) -> 0.94463296 | P40: Calculated value | Q40: Texas Instruments FY2025 reported segment mix x the split above. Power = 50% of TI's reported Analog segment (user-provided split; TI does not report power separately). Signal chain = the other 50% of Analog.
A41: Base-year revenue mix | B41: % | C41: =$C$40/$F$40 -> 0.419266 | D41: =$D$40/$F$40 -> 0.419266 | E41: =$E$40/$F$40 -> 0.161468 | F41: =SUM(C41:E41) -> 1 | P41: Calculated value | Q41: Renormalized to 100% over the three products (reported segments not modeled are excluded).
A42: Base-year revenue | B42: $m | C42: =$F$32*$C$41 -> 419.266 | D42: =$F$32*$D$41 -> 419.266 | E42: =$F$32*$E$41 -> 161.468 | F42: =SUM(C42:E42) -> 1000 | P42: Calculated value | Q42: Division revenue x mix
A43: Base-year average selling price | B43: $/unit | C43: 0.6 | D43: 0.95 | E43: 3.4 | P43: Simulated operational data | Q43: Simulated. Order of magnitude typical for each product type.
A44: Base-year final-test yield | B44: % | C44: 0.95 | D44: 0.93 | E44: 0.88 | P44: Simulated operational data | Q44: Simulated. Good units / units tested. Larger embedded die -> lower yield.
A45: Base-year variable cost per unit produced | B45: $/unit | C45: 0.14 | D45: 0.21 | E45: 0.95 | P45: Simulated operational data | Q45: Simulated. Wafer, package, test consumables per unit started. Calibrated so the base-year division gross margin (57.2%) is close to TI's reported FY2025 57.0%.
A46: Fixed manufacturing cost per month | B46: $m/month | C46: 5.8 | D46: 6.2 | E46: 2.5 | F46: =SUM(C46:E46) -> 14.5 | P46: Simulated operational data | Q46: Simulated. Factory overhead, depreciation, test labor.
...

Sheet Hist_Data
A1: Historical Data - Texas Instruments (reported)
A2: USD millions unless noted. Fiscal years end December 31. Blue = hardcoded reported value from SEC filing.
A3: Simulated data created for portfolio demonstration. It does not represent nonpublic Texas Instruments information. (This tab contains reported public data and calculated values only.)
A5: Line item | B5: Units | C5: FY2021 | D5: FY2022 | E5: FY2023 | F5: FY2024 | G5: FY2025 | H5: Classification | I5: Source (filing, statement page) | J5: Notes | K5: line_id
A6: Income statement
A7: Revenue | B7: $m | C7: 18344 | D7: 20028 | E7: 17519 | F7: 15641 | G7: 17682 | H7: Reported public data | I7: S-002 10-K FY2023 R3.htm; S-001 10-K FY2025 R3.htm | K7: net_sales
A8: Cost of revenue (COR) | B8: $m | C8: 5968 | D8: 6257 | E8: 6500 | F8: 6547 | G8: 7599 | H8: Reported public data | I8: S-002 10-K FY2023 R3.htm; S-001 10-K FY2025 R3.htm | K8: cost_of_sales
A9: Gross profit | B9: $m | C9: 12376 | D9: 13771 | E9: 11019 | F9: 9094 | G9: 10083 | H9: Reported public data | I9: S-002 10-K FY2023 R3.htm; S-001 10-K FY2025 R3.htm | K9: gross_profit
A10: Research and development (R&D) | B10: $m | C10: 1554 | D10: 1670 | E10: 1863 | F10: 1959 | G10: 2083 | H10: Reported public data | I10: S-002 10-K FY2023 R3.htm; S-001 10-K FY2025 R3.htm | K10: rd
A11: Selling, general and administrative (SG&A) | B11: $m | C11: 1666 | D11: 1704 | E11: 1825 | F11: 1794 | G11: 1860 | H11: Reported public data | I11: S-002 10-K FY2023 R3.htm; S-001 10-K FY2025 R3.htm | K11: sga
A12: Restructuring charges/other | B12: $m | C12: 54 | D12: 257 | E12: 0 | F12: -124 | G12: 117 | H12: Reported public data | I12: S-002 10-K FY2023 R3.htm; S-001 10-K FY2025 R3.htm | K12: other_opex:restructuring
A13: Acquisition charges | B13: $m | C13: 142 | D13: 0 | H13: Reported public data | I13: S-002 10-K FY2023 R3.htm | J13: Printed in the FY2023 10-K for FY2021-FY2022 only; blank = not presented, treated as 0. | K13: other_opex:acquisition
A14: Operating profit | B14: $m | C14: 8960 | D14: 10140 | E14: 7331 | F14: 5465 | G14: 6023 | H14: Reported public data | I14: S-002 10-K FY2023 R3.htm; S-001 10-K FY2025 R3.htm | K14: operating_income
A15: Other income (expense), net (OI&E) | B15: $m | C15: 143 | D15: 106 | E15: 440 | F15: 496 | G15: 230 | H15: Reported public data | I15: S-002 10-K FY2023 R3.htm; S-001 10-K FY2025 R3.htm | K15: nonop:other_income
A16: Interest and debt expense | B16: $m | C16: -184 | D16: -214 | E16: -353 | F16: -508 | G16: -543 | H16: Reported public data | I16: S-002 10-K FY2023 R3.htm; S-001 10-K FY2025 R3.htm | J16: Printed as a positive expense; stored negative (effect on pre-tax income). | K16: nonop:interest
A17: Income before income taxes | B17: $m | C17: 8919 | D17: 10032 | E17: 7418 | F17: 5453 | G17: 5710 | H17: Reported public data | I17: S-002 10-K FY2023 R3.htm; S-001 10-K FY2025 R3.htm | K17: pretax_income
A18: Provision for income taxes | B18: $m | C18: 1150 | D18: 1283 | E18: 908 | F18: 654 | G18: 709 | H18: Reported public data | I18: S-002 10-K FY2023 R3.htm; S-001 10-K FY2025 R3.htm | K18: income_tax
A19: Net income | B19: $m | C19: 7769 | D19: 8749 | E19: 6510 | F19: 4799 | G19: 5001 | H19: Reported public data | I19: S-002 10-K FY2023 R3.htm; S-001 10-K FY2025 R3.htm | K19: net_income
A20: Net sales by reported segment / product line
A21: Analog | B21: $m | C21: 14050 | D21: 15359 | E21: 13040 | F21: 12161 | G21: 14006 | H21: Reported public data | I21: S-002 10-K FY2023 R34.htm; S-001 10-K FY2025 R37.htm | J21: Reported segment. Split 50/50 into power management and signal chain in this model (user-provided assumption). | K21: segment:analog
A22: Embedded Processing | B22: $m | C22: 3049 | D22: 3261 | E22: 3368 | F22: 2533 | G22: 2697 | H22: Reported public data | I22: S-002 10-K FY2023 R34.htm; S-001 10-K FY2025 R37.htm | K22: segment:embedded_processing
A23: Other | B23: $m | C23: 1245 | D23: 1408 | E23: 1111 | F23: 947 | G23: 979 | H23: Reported public data | I23: S-002 10-K FY2023 R34.htm; S-001 10-K FY2025 R37.htm | J23: TI's reported Other segment. Not modeled in the division (mix renormalized over the three products). | K23: segment:other
A24: Other segment disclosures
A25: Analog - gross profit | B25: $m | E25: 8425 | F25: 7292 | G25: 8242 | H25: Reported public data | I25: S-001 10-K FY2025 R37.htm | K25: segment_info:analog_gross_profit
A26: Embedded Processing - gross profit | B26: $m | E26: 1875 | F26: 1218 | G26: 1226 | H26: Reported public data | I26: S-001 10-K FY2025 R37.htm | K26: segment_info:embedded_gross_profit
A27: Other - gross profit | B27: $m | E27: 719 | F27: 584 | G27: 615 | H27: Reported public data | I27: S-001 10-K FY2025 R37.htm | K27: segment_info:other_gross_profit
A28: Cash flow statement (selected lines)
A29: Net income | B29: $m | C29: 7769 | D29: 8749 | E29: 6510 | F29: 4799 | G29: 5001 | H29: Reported public data | I29: S-002 10-K FY2023 R8.htm; S-001 10-K FY2025 R7.htm | K29: cf:net_income
A30: Depreciation | B30: $m | C30: 755 | D30: 925 | E30: 1175 | F30: 1508 | G30: 1918 | H30: Reported public data | I30: S-002 10-K FY2023 R8.htm; S-001 10-K FY2025 R7.htm | J30: Depreciation only; TI prints amortization of capitalized software separately. | K30: cf:da
A31: Stock compensation | B31: $m | C31: 230 | D31: 289 | E31: 362 | F31: 387 | G31: 419 | H31: Reported public data | I31: S-002 10-K FY2023 R8.htm; S-001 10-K FY2025 R7.htm | K31: cf:sbc
A32: Accounts receivable | B32: $m | C32: -287 | D32: -194 | E32: 108 | F32: 68 | G32: -244 | H32: Reported public data | I32: S-002 10-K FY2023 R8.htm; S-001 10-K FY2025 R7.htm | K32: wc:receivables
A33: Inventories | B33: $m | C33: 45 | D33: -847 | E33: -1242 | F33: -528 | G33: -277 | H33: Reported public data | I33: S-002 10-K FY2023 R8.htm; S-001 10-K FY2025 R7.htm | K33: wc:inventories
A34: Prepaid expenses and other current assets | B34: $m | C34: 57 | D34: 6 | E34: 46 | F34: 7 | G34: 10 | H34: Reported public data | I34: S-002 10-K FY2023 R8.htm; S-001 10-K FY2025 R7.htm | K34: wc:prepaid
A35: Accounts payable and accrued expenses | B35: $m | C35: 33 | D35: 106 | E35: -33 | F35: 125 | G35: 77 | H35: Reported public data | I35: S-002 10-K FY2023 R8.htm; S-001 10-K FY2025 R7.htm | K35: wc:payables_accrued
A36: Accrued compensation | B36: $m | C36: 7 | D36: 22 | E36: 29 | F36: -12 | G36: -28 | H36: Reported public data | I36: S-002 10-K FY2023 R8.htm; S-001 10-K FY2025 R7.htm | K36: wc:accrued_compensation
A37: Income taxes payable | B37: $m | C37: -20 | D37: 94 | E37: -7 | F37: 597 | G37: 191 | H37: Reported public data | I37: S-002 10-K FY2023 R8.htm; S-001 10-K FY2025 R7.htm | K37: wc:income_tax
A38: Cash flows from operating activities | B38: $m | C38: 8756 | D38: 8720 | E38: 6420 | F38: 6318 | G38: 7153 | H38: Reported public data | I38: S-002 10-K FY2023 R8.htm; S-001 10-K FY2025 R7.htm | K38: cf:cfo
A39: Capital expenditures | B39: $m | C39: -2462 | D39: -2797 | E39: -5071 | F39: -4820 | G39: -4550 | H39: Reported public data | I39: S-002 10-K FY2023 R8.htm; S-001 10-K FY2025 R7.htm | J39: Printed as a cash outflow (negative). Analysis converts to positive spend. | K39: cf:capex
A40: Cash flows from investing activities | B40: $m | C40: -4095 | D40: -3583 | E40: -4362 | F40: -3202 | G40: -1439 | H40: Reported public data | I40: S-002 10-K FY2023 R8.htm; S-001 10-K FY2025 R7.htm | K40: cf:cfi
A41: Cash flows from financing activities | B41: $m | C41: -3137 | D41: -6718 | E41: -2144 | F41: -2880 | G41: -5689 | H41: Reported public data | I41: S-002 10-K FY2023 R8.htm; S-001 10-K FY2025 R7.htm | K41: cf:cff
...

Sheet Hist_Analysis
A1: Historical Financial Analysis - Texas Instruments
A2: All figures are formulas on Hist_Data. Green = direct link to Hist_Data; black = calculation.
A3: Simulated data created for portfolio demonstration. It does not represent nonpublic Texas Instruments information. (This tab contains reported public data and calculated values only.)
A5: Metric | B5: Units | C5: FY2021 | D5: FY2022 | E5: FY2023 | F5: FY2024 | G5: FY2025 | H5: Classification | I5: Formula / definition
A6: Growth and profitability
A7: Net sales | B7: $m | C7: =Hist_Data!$C$7 -> 18344 | D7: =Hist_Data!$D$7 -> 20028 | E7: =Hist_Data!$E$7 -> 17519 | F7: =Hist_Data!$F$7 -> 15641 | G7: =Hist_Data!$G$7 -> 17682 | H7: Calculated value | I7: Link: Hist_Data net sales
A8: Net sales growth | B8: % | C8: n/a | D8: =IFERROR(Hist_Data!$D$7/Hist_Data!$C$7-1,"") -> 0.091801134 | E8: =IFERROR(Hist_Data!$E$7/Hist_Data!$D$7-1,"") -> -0.12527462 | F8: =IFERROR(Hist_Data!$F$7/Hist_Data!$E$7-1,"") -> -0.1071979 | G8: =IFERROR(Hist_Data!$G$7/Hist_Data!$F$7-1,"") -> 0.13049038 | H8: Calculated value | I8: Net sales / prior-year net sales - 1
A9: Gross margin | B9: % | C9: =IFERROR(Hist_Data!$C$9/Hist_Data!$C$7,"") -> 0.67466201 | D9: =IFERROR(Hist_Data!$D$9/Hist_Data!$D$7,"") -> 0.68758738 | E9: =IFERROR(Hist_Data!$E$9/Hist_Data!$E$7,"") -> 0.62897426 | F9: =IFERROR(Hist_Data!$F$9/Hist_Data!$F$7,"") -> 0.58142063 | G9: =IFERROR(Hist_Data!$G$9/Hist_Data!$G$7,"") -> 0.57024092 | H9: Calculated value | I9: Gross profit / net sales
A10: R&D % of sales | B10: % | C10: =IFERROR(Hist_Data!$C$10/Hist_Data!$C$7,"") -> 0.084714348 | D10: =IFERROR(Hist_Data!$D$10/Hist_Data!$D$7,"") -> 0.083383263 | E10: =IFERROR(Hist_Data!$E$10/Hist_Data!$E$7,"") -> 0.10634169 | F10: =IFERROR(Hist_Data!$F$10/Hist_Data!$F$7,"") -> 0.12524775 | G10: =IFERROR(Hist_Data!$G$10/Hist_Data!$G$7,"") -> 0.11780342 | H10: Calculated value | I10: Research and development / net sales
A11: SG&A % of sales | B11: % | C11: =IFERROR(Hist_Data!$C$11/Hist_Data!$C$7,"") -> 0.090819887 | D11: =IFERROR(Hist_Data!$D$11/Hist_Data!$D$7,"") -> 0.085080887 | E11: =IFERROR(Hist_Data!$E$11/Hist_Data!$E$7,"") -> 0.10417261 | F11: =IFERROR(Hist_Data!$F$11/Hist_Data!$F$7,"") -> 0.11469855 | G11: =IFERROR(Hist_Data!$G$11/Hist_Data!$G$7,"") -> 0.10519172 | H11: Calculated value | I11: SG&A / net sales
A12: Operating margin (GAAP) | B12: % | C12: =IFERROR(Hist_Data!$C$14/Hist_Data!$C$7,"") -> 0.48844309 | D12: =IFERROR(Hist_Data!$D$14/Hist_Data!$D$7,"") -> 0.50629119 | E12: =IFERROR(Hist_Data!$E$14/Hist_Data!$E$7,"") -> 0.41845996 | F12: =IFERROR(Hist_Data!$F$14/Hist_Data!$F$7,"") -> 0.34940221 | G12: =IFERROR(Hist_Data!$G$14/Hist_Data!$G$7,"") -> 0.34062889 | H12: Calculated value | I12: Operating income / net sales
A13: Other operating items (sum of reported components) | B13: $m | C13: =(N(Hist_Data!$C$12)+N(Hist_Data!$C$13)) -> 196 | D13: =(N(Hist_Data!$D$12)+N(Hist_Data!$D$13)) -> 257 | E13: =(N(Hist_Data!$E$12)+N(Hist_Data!$E$13)) -> 0 | F13: =(N(Hist_Data!$F$12)+N(Hist_Data!$F$13)) -> -124 | G13: =(N(Hist_Data!$G$12)+N(Hist_Data!$G$13)) -> 117 | H13: Calculated value | I13: Sum of: restructuring charges/other, acquisition charges
A14: Operating income before other operating items | B14: $m | C14: =Hist_Data!$C$14+$C$13 -> 9156 | D14: =Hist_Data!$D$14+$D$13 -> 10397 | E14: =Hist_Data!$E$14+$E$13 -> 7331 | F14: =Hist_Data!$F$14+$F$13 -> 5341 | G14: =Hist_Data!$G$14+$G$13 -> 6140 | H14: Calculated value | I14: Operating income + other operating items (restructuring charges/other, acquisition charges). Analyst calculation - NOT Texas Instruments's reported non-GAAP measure.
A15: Margin before other operating items | B15: % | C15: =IFERROR($C$14/Hist_Data!$C$7,"") -> 0.49912778 | D15: =IFERROR($D$14/Hist_Data!$D$7,"") -> 0.51912323 | E15: =IFERROR($E$14/Hist_Data!$E$7,"") -> 0.41845996 | F15: =IFERROR($F$14/Hist_Data!$F$7,"") -> 0.34147433 | G15: =IFERROR($G$14/Hist_Data!$G$7,"") -> 0.34724579 | H15: Calculated value | I15: Row above / net sales. Closest proxy for a product division's operating margin.
A16: Net margin | B16: % | C16: =IFERROR(Hist_Data!$C$19/Hist_Data!$C$7,"") -> 0.42351723 | D16: =IFERROR(Hist_Data!$D$19/Hist_Data!$D$7,"") -> 0.43683843 | E16: =IFERROR(Hist_Data!$E$19/Hist_Data!$E$7,"") -> 0.37159655 | F16: =IFERROR(Hist_Data!$F$19/Hist_Data!$F$7,"") -> 0.30682181 | G16: =IFERROR(Hist_Data!$G$19/Hist_Data!$G$7,"") -> 0.28283 | H16: Calculated value | I16: Net income / net sales
A17: Effective tax rate | B17: % | C17: =IF(ABS(Hist_Data!$C$17)<0.02*Hist_Data!$C$7,"n.m.",IFERROR(Hist_Data!$C$18/Hist_Data!$C$17,"")) -> 0.12893822 | D17: =IF(ABS(Hist_Data!$D$17)<0.02*Hist_Data!$D$7,"n.m.",IFERROR(Hist_Data!$D$18/Hist_Data!$D$17,"")) -> 0.12789075 | E17: =IF(ABS(Hist_Data!$E$17)<0.02*Hist_Data!$E$7,"n.m.",IFERROR(Hist_Data!$E$18/Hist_Data!$E$17,"")) -> 0.12240496 | F17: =IF(ABS(Hist_Data!$F$17)<0.02*Hist_Data!$F$7,"n.m.",IFERROR(Hist_Data!$F$18/Hist_Data!$F$17,"")) -> 0.11993398 | G17: =IF(ABS(Hist_Data!$G$17)<0.02*Hist_Data!$G$7,"n.m.",IFERROR(Hist_Data!$G$18/Hist_Data!$G$17,"")) -> 0.12416813 | H17: Calculated value | I17: Income tax / income before taxes. Shows n.m. (not meaningful) when pre-tax income is under 2% of sales.
A18: Incremental gross margin (change in GP / change in sales) | B18: % | C18: n/a | D18: =IFERROR((Hist_Data!$D$9-Hist_Data!$C$9)/(Hist_Data!$D$7-Hist_Data!$C$7),"") -> 0.8283848 | E18: =IFERROR((Hist_Data!$E$9-Hist_Data!$D$9)/(Hist_Data!$E$7-Hist_Data!$D$7),"") -> 1.0968513 | F18: =IFERROR((Hist_Data!$F$9-Hist_Data!$E$9)/(Hist_Data!$F$7-Hist_Data!$E$7),"") -> 1.0250266 | G18: =IFERROR((Hist_Data!$G$9-Hist_Data!$F$9)/(Hist_Data!$G$7-Hist_Data!$F$7),"") -> 0.48456639 | H18: Calculated value | I18: Shows operating leverage: how much gross profit moved per $1 of sales change (fixed-cost absorption)
A19: Reported segment / product-line mix and growth
A20: Analog - share of net sales | B20: % | C20: =IFERROR(Hist_Data!$C$21/Hist_Data!$C$7,"") -> 0.76591801 | D20: =IFERROR(Hist_Data!$D$21/Hist_Data!$D$7,"") -> 0.76687637 | E20: =IFERROR(Hist_Data!$E$21/Hist_Data!$E$7,"") -> 0.74433472 | F20: =IFERROR(Hist_Data!$F$21/Hist_Data!$F$7,"") -> 0.77750783 | G20: =IFERROR(Hist_Data!$G$21/Hist_Data!$G$7,"") -> 0.79210497 | H20: Calculated value | I20: Analog sales / net sales
A21: Embedded Processing - share of net sales | B21: % | C21: =IFERROR(Hist_Data!$C$22/Hist_Data!$C$7,"") -> 0.16621239 | D21: =IFERROR(Hist_Data!$D$22/Hist_Data!$D$7,"") -> 0.16282205 | E21: =IFERROR(Hist_Data!$E$22/Hist_Data!$E$7,"") -> 0.19224842 | F21: =IFERROR(Hist_Data!$F$22/Hist_Data!$F$7,"") -> 0.16194617 | G21: =IFERROR(Hist_Data!$G$22/Hist_Data!$G$7,"") -> 0.15252799 | H21: Calculated value | I21: Embedded Processing sales / net sales
A22: Other - share of net sales | B22: % | C22: =IFERROR(Hist_Data!$C$23/Hist_Data!$C$7,"") -> 0.067869603 | D22: =IFERROR(Hist_Data!$D$23/Hist_Data!$D$7,"") -> 0.070301578 | E22: =IFERROR(Hist_Data!$E$23/Hist_Data!$E$7,"") -> 0.063416862 | F22: =IFERROR(Hist_Data!$F$23/Hist_Data!$F$7,"") -> 0.060546001 | G22: =IFERROR(Hist_Data!$G$23/Hist_Data!$G$7,"") -> 0.05536704 | H22: Calculated value | I22: Other sales / net sales
A23: Mix total (must equal 100%) | B23: % | C23: =$C$20+$C$21+$C$22 -> 1 | D23: =$D$20+$D$21+$D$22 -> 1 | E23: =$E$20+$E$21+$E$22 -> 1 | F23: =$F$20+$F$21+$F$22 -> 1 | G23: =$G$20+$G$21+$G$22 -> 1 | H23: Calculated value | I23: Sum of the segment shares
A24: Analog - growth | B24: % | C24: n/a | D24: =IFERROR(Hist_Data!$D$21/Hist_Data!$C$21-1,"") -> 0.09316726 | E24: =IFERROR(Hist_Data!$E$21/Hist_Data!$D$21-1,"") -> -0.15098639 | F24: =IFERROR(Hist_Data!$F$21/Hist_Data!$E$21-1,"") -> -0.067407975 | G24: =IFERROR(Hist_Data!$G$21/Hist_Data!$F$21-1,"") -> 0.1517145 | H24: Calculated value | I24: Analog sales / prior year - 1
A25: Embedded Processing - growth | B25: % | C25: n/a | D25: =IFERROR(Hist_Data!$D$22/Hist_Data!$C$22-1,"") -> 0.069530994 | E25: =IFERROR(Hist_Data!$E$22/Hist_Data!$D$22-1,"") -> 0.032812021 | F25: =IFERROR(Hist_Data!$F$22/Hist_Data!$E$22-1,"") -> -0.24792162 | G25: =IFERROR(Hist_Data!$G$22/Hist_Data!$F$22-1,"") -> 0.064745361 | H25: Calculated value | I25: Embedded Processing sales / prior year - 1
A26: Other - growth | B26: % | C26: n/a | D26: =IFERROR(Hist_Data!$D$23/Hist_Data!$C$23-1,"") -> 0.13092369 | E26: =IFERROR(Hist_Data!$E$23/Hist_Data!$D$23-1,"") -> -0.2109375 | F26: =IFERROR(Hist_Data!$F$23/Hist_Data!$E$23-1,"") -> -0.14761476 | G26: =IFERROR(Hist_Data!$G$23/Hist_Data!$F$23-1,"") -> 0.033790919 | H26: Calculated value | I26: Other sales / prior year - 1
A27: Cash flow and free cash flow (project definition)
A28: Net income | B28: $m | C28: =Hist_Data!$C$19 -> 7769 | D28: =Hist_Data!$D$19 -> 8749 | E28: =Hist_Data!$E$19 -> 6510 | F28: =Hist_Data!$F$19 -> 4799 | G28: =Hist_Data!$G$19 -> 5001 | H28: Calculated value | I28: Link: Hist_Data net income
A29: Depreciation and amortization | B29: $m | C29: =Hist_Data!$C$30 -> 755 | D29: =Hist_Data!$D$30 -> 925 | E29: =Hist_Data!$E$30 -> 1175 | F29: =Hist_Data!$F$30 -> 1508 | G29: =Hist_Data!$G$30 -> 1918 | H29: Calculated value | I29: Link: Hist_Data D&A (cash flow statement)
A30: Capital expenditures (positive = spend) | B30: $m | C30: =-Hist_Data!$C$39 -> 2462 | D30: =-Hist_Data!$D$39 -> 2797 | E30: =-Hist_Data!$E$39 -> 5071 | F30: =-Hist_Data!$F$39 -> 4820 | G30: =-Hist_Data!$G$39 -> 4550 | H30: Calculated value | I30: Negative of capex as printed. Cash-flow statement prints capex negative.
A31: Increase in working capital | B31: $m | C31: =-(N(Hist_Data!$C$32)+N(Hist_Data!$C$33)+N(Hist_Data!$C$34)+N(Hist_Data!$C$35)+N(Hist_Data!$C$36)+N(Hist_Data!$C$37)) -> 165 | D31: =-(N(Hist_Data!$D$32)+N(Hist_Data!$D$33)+N(Hist_Data!$D$34)+N(Hist_Data!$D$35)+N(Hist_Data!$D$36)+N(Hist_Data!$D$37)) -> 813 | E31: =-(N(Hist_Data!$E$32)+N(Hist_Data!$E$33)+N(Hist_Data!$E$34)+N(Hist_Data!$E$35)+N(Hist_Data!$E$36)+N(Hist_Data!$E$37)) -> 1099 | F31: =-(N(Hist_Data!$F$32)+N(Hist_Data!$F$33)+N(Hist_Data!$F$34)+N(Hist_Data!$F$35)+N(Hist_Data!$F$36)+N(Hist_Data!$F$37)) -> -257 | G31: =-(N(Hist_Data!$G$32)+N(Hist_Data!$G$33)+N(Hist_Data!$G$34)+N(Hist_Data!$G$35)+N(Hist_Data!$G$36)+N(Hist_Data!$G$37)) -> 271 | H31: Calculated value | I31: Negative of the sum of the 6 cash-flow working-capital lines. Positive = cash absorbed by working capital.
A32: Free cash flow (project definition) | B32: $m | C32: =$C$28+$C$29-$C$30-$C$31 -> 5897 | D32: =$D$28+$D$29-$D$30-$D$31 -> 6064 | E32: =$E$28+$E$29-$E$30-$E$31 -> 1515 | F32: =$F$28+$F$29-$F$30-$F$31 -> 1744 | G32: =$G$28+$G$29-$G$30-$G$31 -> 2098 | H32: Calculated value | I32: Net income + D&A - capex - increase in working capital (project formula)
A33: Other non-cash items in CFO (SBC, deferred tax, other) | B33: $m | C33: =Hist_Data!$C$38-$C$28-$C$29+$C$31 -> 397 | D33: =Hist_Data!$D$38-$D$28-$D$29+$D$31 -> -141 | E33: =Hist_Data!$E$38-$E$28-$E$29+$E$31 -> -166 | F33: =Hist_Data!$F$38-$F$28-$F$29+$F$31 -> -246 | G33: =Hist_Data!$G$38-$G$28-$G$29+$G$31 -> 505 | H33: Calculated value | I33: CFO - net income - D&A + increase in WC. Explains the gap to the CFO-based FCF below.
A34: Free cash flow (CFO - capex, common market definition) | B34: $m | C34: =Hist_Data!$C$38-$C$30 -> 6294 | D34: =Hist_Data!$D$38-$D$30 -> 5923 | E34: =Hist_Data!$E$38-$E$30 -> 1349 | F34: =Hist_Data!$F$38-$F$30 -> 1498 | G34: =Hist_Data!$G$38-$G$30 -> 2603 | H34: Calculated value | I34: Net cash from operations - capex. Reconciles to project FCF + other non-cash items (see Checks).
A35: FCF margin (project definition) | B35: % | C35: =IFERROR($C$32/Hist_Data!$C$7,"") -> 0.32146751 | D35: =IFERROR($D$32/Hist_Data!$D$7,"") -> 0.30277611 | E35: =IFERROR($E$32/Hist_Data!$E$7,"") -> 0.086477539 | F35: =IFERROR($F$32/Hist_Data!$F$7,"") -> 0.11150182 | G35: =IFERROR($G$32/Hist_Data!$G$7,"") -> 0.11865174 | H35: Calculated value | I35: Project FCF / net sales
A36: FCF conversion (project FCF / net income) | B36: x | C36: =IF(ABS($C$28)<0.02*Hist_Data!$C$7,"n.m.",IFERROR($C$32/$C$28,"")) -> 0.75904235 | D36: =IF(ABS($D$28)<0.02*Hist_Data!$D$7,"n.m.",IFERROR($D$32/$D$28,"")) -> 0.69310778 | E36: =IF(ABS($E$28)<0.02*Hist_Data!$E$7,"n.m.",IFERROR($E$32/$E$28,"")) -> 0.23271889 | F36: =IF(ABS($F$28)<0.02*Hist_Data!$F$7,"n.m.",IFERROR($F$32/$F$28,"")) -> 0.36340904 | G36: =IF(ABS($G$28)<0.02*Hist_Data!$G$7,"n.m.",IFERROR($G$32/$G$28,"")) -> 0.4195161 | H36: Calculated value | I36: Project FCF / net income. Shows n.m. when net income is under 2% of sales.
A37: Capex % of sales | B37: % | C37: =IFERROR($C$30/Hist_Data!$C$7,"") -> 0.13421282 | D37: =IFERROR($D$30/Hist_Data!$D$7,"") -> 0.13965448 | E37: =IFERROR($E$30/Hist_Data!$E$7,"") -> 0.28945716 | F37: =IFERROR($F$30/Hist_Data!$F$7,"") -> 0.30816444 | G37: =IFERROR($G$30/Hist_Data!$G$7,"") -> 0.25732383 | H37: Calculated value | I37: Capex / net sales - anchor for the forecast capex assumption
A38: D&A % of sales | B38: % | C38: =IFERROR(Hist_Data!$C$30/Hist_Data!$C$7,"") -> 0.041157872 | D38: =IFERROR(Hist_Data!$D$30/Hist_Data!$D$7,"") -> 0.046185341 | E38: =IFERROR(Hist_Data!$E$30/Hist_Data!$E$7,"") -> 0.067070038 | F38: =IFERROR(Hist_Data!$F$30/Hist_Data!$F$7,"") -> 0.096413273 | G38: =IFERROR(Hist_Data!$G$30/Hist_Data!$G$7,"") -> 0.10847189 | H38: Calculated value | I38: D&A / net sales
A39: Share-based compensation % of sales | B39: % | C39: =IFERROR(Hist_Data!$C$31/Hist_Data!$C$7,"") -> 0.01253816 | D39: =IFERROR(Hist_Data!$D$31/Hist_Data!$D$7,"") -> 0.014429798 | E39: =IFERROR(Hist_Data!$E$31/Hist_Data!$E$7,"") -> 0.02066328 | F39: =IFERROR(Hist_Data!$F$31/Hist_Data!$F$7,"") -> 0.024742664 | G39: =IFERROR(Hist_Data!$G$31/Hist_Data!$G$7,"") -> 0.023696414 | H39: Calculated value | I39: SBC / net sales
A40: Capex / depreciation & amortization | B40: x | C40: =IFERROR($C$30/Hist_Data!$C$30,"") -> 3.2609272 | D40: =IFERROR($D$30/Hist_Data!$D$30,"") -> 3.0237838 | E40: =IFERROR($E$30/Hist_Data!$E$30,"") -> 4.3157447 | F40: =IFERROR($F$30/Hist_Data!$F$30,"") -> 3.1962865 | G40: =IFERROR($G$30/Hist_Data!$G$30,"") -> 2.3722628 | H40: Calculated value | I40: <1.0x means spending less than D&A (asset base shrinking or amortization-heavy D&A)
A41: Working capital and asset efficiency (year-end balances)
...

Sheet Ops_Model
A1: Product Operating Model - FY2026 monthly (active scenario)
A2: Units in millions, money in $m, prices in $/unit. Every row traces to Assumptions. Black = formula.
A3: Simulated data created for portfolio demonstration. It does not represent nonpublic Texas Instruments information.
A4: Scenario shown: | B4: =Assumptions!$C$6 -> Base
A6: Line item | B6: Units | C6: =Assumptions!C$72 -> 46023 | D6: =Assumptions!D$72 -> 46054 | E6: =Assumptions!E$72 -> 46082 | F6: =Assumptions!F$72 -> 46113 | G6: =Assumptions!G$72 -> 46143 | H6: =Assumptions!H$72 -> 46174 | I6: =Assumptions!I$72 -> 46204 | J6: =Assumptions!J$72 -> 46235 | ... N6: =Assumptions!N$72 -> 46357 | O6: FY2026 | P6: Classification | Q6: Formula
A7: Power-management chips - Simulated data created for portfolio demonstration. It does not represent nonpublic Texas Instruments information.
A8: Seasonality factor | B8: x | C8: =Assumptions!C$73 -> 0.94 | D8: =Assumptions!D$73 -> 0.96 | E8: =Assumptions!E$73 -> 1.02 | F8: =Assumptions!F$73 -> 0.99 | G8: =Assumptions!G$73 -> 1 | H8: =Assumptions!H$73 -> 1.03 | I8: =Assumptions!I$73 -> 1.02 | J8: =Assumptions!J$73 -> 1.03 | ... N8: =Assumptions!N$73 -> 0.96 | O8: =SUM(C8:N8) -> 12 | P8: Calculated value (simulated inputs) | Q8: Link: Assumptions section E
A9: Customer demand | B9: m units | C9: =Assumptions!$C$63*C8/12 -> 64.042882 | D9: =Assumptions!$C$63*D8/12 -> 65.405496 | E9: =Assumptions!$C$63*E8/12 -> 69.49334 | F9: =Assumptions!$C$63*F8/12 -> 67.449418 | G9: =Assumptions!$C$63*G8/12 -> 68.130725 | H9: =Assumptions!$C$63*H8/12 -> 70.174647 | I9: =Assumptions!$C$63*I8/12 -> 69.49334 | J9: =Assumptions!$C$63*J8/12 -> 70.174647 | ... N9: =Assumptions!$C$63*N8/12 -> 65.405496 | O9: =SUM(C9:N9) -> 817.5687 | P9: Calculated value (simulated inputs) | Q9: FY2026 demand x seasonality / 12
A10: Internal final-test capacity | B10: m units | C10: =Assumptions!$C$47 -> 88 | D10: =Assumptions!$C$47 -> 88 | E10: =Assumptions!$C$47 -> 88 | F10: =Assumptions!$C$47 -> 88 | G10: =Assumptions!$C$47 -> 88 | H10: =Assumptions!$C$47 -> 88 | I10: =Assumptions!$C$47 -> 88 | J10: =Assumptions!$C$47 -> 88 | ... N10: =Assumptions!$C$47 -> 88 | O10: =SUM(C10:N10) -> 1056 | P10: Calculated value (simulated inputs) | Q10: Monthly capacity (Assumptions D)
A11: Capacity utilization | B11: % | C11: =Assumptions!$C$66 -> 0.78 | D11: =Assumptions!$C$66 -> 0.78 | E11: =Assumptions!$C$66 -> 0.78 | F11: =Assumptions!$C$66 -> 0.78 | G11: =Assumptions!$C$66 -> 0.78 | H11: =Assumptions!$C$66 -> 0.78 | I11: =Assumptions!$C$66 -> 0.78 | J11: =Assumptions!$C$66 -> 0.78 | ... N11: =Assumptions!$C$66 -> 0.78 | O11: =IFERROR(O12/O10,0) -> 0.78 | P11: Calculated value (simulated inputs) | Q11: Scenario utilization. FY = units produced / capacity
A12: Units produced (tested) | B12: m units | C12: =C10*C11 -> 68.64 | D12: =D10*D11 -> 68.64 | E12: =E10*E11 -> 68.64 | F12: =F10*F11 -> 68.64 | G12: =G10*G11 -> 68.64 | H12: =H10*H11 -> 68.64 | I12: =I10*I11 -> 68.64 | J12: =J10*J11 -> 68.64 | ... N12: =N10*N11 -> 68.64 | O12: =SUM(C12:N12) -> 823.68 | P12: Calculated value (simulated inputs) | Q12: Capacity x utilization
A13: Manufacturing yield (final test) | B13: % | C13: =Assumptions!$C$65 -> 0.95 | D13: =Assumptions!$C$65 -> 0.95 | E13: =Assumptions!$C$65 -> 0.95 | F13: =Assumptions!$C$65 -> 0.95 | G13: =Assumptions!$C$65 -> 0.95 | H13: =Assumptions!$C$65 -> 0.95 | I13: =Assumptions!$C$65 -> 0.95 | J13: =Assumptions!$C$65 -> 0.95 | ... N13: =Assumptions!$C$65 -> 0.95 | O13: =IFERROR(O14/O12,0) -> 0.95 | P13: Calculated value (simulated inputs) | Q13: Scenario yield. FY = good units / units produced
A14: Good units produced | B14: m units | C14: =C12*C13 -> 65.208 | D14: =D12*D13 -> 65.208 | E14: =E12*E13 -> 65.208 | F14: =F12*F13 -> 65.208 | G14: =G12*G13 -> 65.208 | H14: =H12*H13 -> 65.208 | I14: =I12*I13 -> 65.208 | J14: =J12*J13 -> 65.208 | ... N14: =N12*N13 -> 65.208 | O14: =SUM(C14:N14) -> 782.496 | P14: Calculated value (simulated inputs) | Q14: Units produced x yield
A15: Opening finished-goods inventory | B15: m units | C15: =Assumptions!$C$68 -> 58.231389 | D15: =C18 -> 59.396507 | E15: =D18 -> 59.199011 | F15: =E18 -> 54.913672 | G15: =F18 -> 52.672254 | H15: =G18 -> 49.749529 | I15: =H18 -> 44.782882 | J15: =I18 -> 40.497543 | K15: =J18 -> 35.530896 | ... N15: =M18 -> 23.356185 | O15: =C15 -> 58.231389 | P15: Calculated value (simulated inputs) | Q15: First month: Assumptions opening balance; then prior month's closing
A16: Available good units | B16: m units | C16: =C15+C14 -> 123.43939 | D16: =D15+D14 -> 124.60451 | E16: =E15+E14 -> 124.40701 | F16: =F15+F14 -> 120.12167 | G16: =G15+G14 -> 117.88025 | H16: =H15+H14 -> 114.95753 | I16: =I15+I14 -> 109.99088 | J16: =J15+J14 -> 105.70554 | ... N16: =N15+N14 -> 88.564185 | P16: Calculated value (simulated inputs) | Q16: Opening inventory + good units produced
A17: Units sold | B17: m units | C17: =MIN(C9,C16) -> 64.042882 | D17: =MIN(D9,D16) -> 65.405496 | E17: =MIN(E9,E16) -> 69.49334 | F17: =MIN(F9,F16) -> 67.449418 | G17: =MIN(G9,G16) -> 68.130725 | H17: =MIN(H9,H16) -> 70.174647 | I17: =MIN(I9,I16) -> 69.49334 | J17: =MIN(J9,J16) -> 70.174647 | ... N17: =MIN(N9,N16) -> 65.405496 | O17: =SUM(C17:N17) -> 817.5687 | P17: Calculated value (simulated inputs) | Q17: MIN(customer demand, available good units)
A18: Closing finished-goods inventory | B18: m units | C18: =C16-C17 -> 59.396507 | D18: =D16-D17 -> 59.199011 | E18: =E16-E17 -> 54.913672 | F18: =F16-F17 -> 52.672254 | G18: =G16-G17 -> 49.749529 | H18: =H16-H17 -> 44.782882 | I18: =I16-I17 -> 40.497543 | J18: =J16-J17 -> 35.530896 | ... N18: =N16-N17 -> 23.158689 | O18: =N18 -> 23.158689 | P18: Calculated value (simulated inputs) | Q18: Available - units sold
A19: Unmet demand (supply shortfall) | B19: m units | C19: =C9-C17 -> 0 | D19: =D9-D17 -> 0 | E19: =E9-E17 -> 0 | F19: =F9-F17 -> 0 | G19: =G9-G17 -> 0 | H19: =H9-H17 -> 0 | I19: =I9-I17 -> 0 | J19: =J9-J17 -> 0 | ... N19: =N9-N17 -> 0 | O19: =SUM(C19:N19) -> 0 | P19: Calculated value (simulated inputs) | Q19: Demand - units sold. >0 means lost or delayed sales
A20: Demand / good-unit capacity (risk ratio) | B20: x | C20: =IFERROR(C9/(C10*C13),0) -> 0.76606318 | D20: =IFERROR(D9/(D10*D13),0) -> 0.78236239 | E20: =IFERROR(E9/(E10*E13),0) -> 0.83126004 | F20: =IFERROR(F9/(F10*F13),0) -> 0.80681122 | G20: =IFERROR(G9/(G10*G13),0) -> 0.81496083 | H20: =IFERROR(H9/(H10*H13),0) -> 0.83940965 | I20: =IFERROR(I9/(I10*I13),0) -> 0.83126004 | J20: =IFERROR(J9/(J10*J13),0) -> 0.83940965 | ... O20: =IFERROR(O9/(O10*O13),0) -> 0.81496083 | P20: Calculated value (simulated inputs) | Q20: Demand / (capacity x yield) = share of full-load good output needed. Feeds the risk heat map
A21: Average selling price | B21: $/unit | C21: =Assumptions!$C$64 -> 0.594 | D21: =Assumptions!$C$64 -> 0.594 | E21: =Assumptions!$C$64 -> 0.594 | F21: =Assumptions!$C$64 -> 0.594 | G21: =Assumptions!$C$64 -> 0.594 | H21: =Assumptions!$C$64 -> 0.594 | I21: =Assumptions!$C$64 -> 0.594 | J21: =Assumptions!$C$64 -> 0.594 | ... N21: =Assumptions!$C$64 -> 0.594 | O21: =IFERROR(O22/O17,0) -> 0.594 | P21: Calculated value (simulated inputs) | Q21: Scenario ASP. FY = revenue / units sold
A22: Revenue | B22: $m | C22: =C17*C21 -> 38.041472 | D22: =D17*D21 -> 38.850865 | E22: =E17*E21 -> 41.279044 | F22: =F17*F21 -> 40.064954 | G22: =G17*G21 -> 40.469651 | H22: =H17*H21 -> 41.68374 | I22: =I17*I21 -> 41.279044 | J22: =J17*J21 -> 41.68374 | ... N22: =N17*N21 -> 38.850865 | O22: =SUM(C22:N22) -> 485.63581 | P22: Calculated value (simulated inputs) | Q22: Units sold x ASP
A23: Variable cost per unit produced | B23: $/unit | C23: =Assumptions!$C$67 -> 0.1442 | D23: =Assumptions!$C$67 -> 0.1442 | E23: =Assumptions!$C$67 -> 0.1442 | F23: =Assumptions!$C$67 -> 0.1442 | G23: =Assumptions!$C$67 -> 0.1442 | H23: =Assumptions!$C$67 -> 0.1442 | I23: =Assumptions!$C$67 -> 0.1442 | J23: =Assumptions!$C$67 -> 0.1442 | ... N23: =Assumptions!$C$67 -> 0.1442 | O23: =IFERROR(O24/O12,0) -> 0.1442 | P23: Calculated value (simulated inputs) | Q23: Scenario variable cost per unit
A24: Variable manufacturing cost | B24: $m | C24: =C12*C23 -> 9.897888 | D24: =D12*D23 -> 9.897888 | E24: =E12*E23 -> 9.897888 | F24: =F12*F23 -> 9.897888 | G24: =G12*G23 -> 9.897888 | H24: =H12*H23 -> 9.897888 | I24: =I12*I23 -> 9.897888 | J24: =J12*J23 -> 9.897888 | ... N24: =N12*N23 -> 9.897888 | O24: =SUM(C24:N24) -> 118.77466 | P24: Calculated value (simulated inputs) | Q24: Units produced x variable cost per unit
A25: Fixed manufacturing cost | B25: $m | C25: =Assumptions!$C$46 -> 5.8 | D25: =Assumptions!$C$46 -> 5.8 | E25: =Assumptions!$C$46 -> 5.8 | F25: =Assumptions!$C$46 -> 5.8 | G25: =Assumptions!$C$46 -> 5.8 | H25: =Assumptions!$C$46 -> 5.8 | I25: =Assumptions!$C$46 -> 5.8 | J25: =Assumptions!$C$46 -> 5.8 | ... N25: =Assumptions!$C$46 -> 5.8 | O25: =SUM(C25:N25) -> 69.6 | P25: Calculated value (simulated inputs) | Q25: Monthly fixed cost (Assumptions D)
A26: Total manufacturing cost | B26: $m | C26: =C24+C25 -> 15.697888 | D26: =D24+D25 -> 15.697888 | E26: =E24+E25 -> 15.697888 | F26: =F24+F25 -> 15.697888 | G26: =G24+G25 -> 15.697888 | H26: =H24+H25 -> 15.697888 | I26: =I24+I25 -> 15.697888 | J26: =J24+J25 -> 15.697888 | ... N26: =N24+N25 -> 15.697888 | O26: =SUM(C26:N26) -> 188.37466 | P26: Calculated value (simulated inputs) | Q26: Variable + fixed manufacturing cost
A27: Cost per good unit | B27: $/unit | C27: =IFERROR(C26/C14,0) -> 0.24073562 | D27: =IFERROR(D26/D14,0) -> 0.24073562 | E27: =IFERROR(E26/E14,0) -> 0.24073562 | F27: =IFERROR(F26/F14,0) -> 0.24073562 | G27: =IFERROR(G26/G14,0) -> 0.24073562 | H27: =IFERROR(H26/H14,0) -> 0.24073562 | I27: =IFERROR(I26/I14,0) -> 0.24073562 | J27: =IFERROR(J26/J14,0) -> 0.24073562 | ... O27: =IFERROR(O26/O14,0) -> 0.24073562 | P27: Calculated value (simulated inputs) | Q27: Total manufacturing cost / good units. Rises when yield or utilization falls
A28: Opening inventory value | B28: $m | C28: =Assumptions!$C$69 -> 14.381468 | D28: =C31 -> 14.47357 | E28: =D31 -> 14.334317 | F28: =E31 -> 13.256316 | G28: =F31 -> 12.696154 | H28: =G31 -> 11.983264 | I28: =H31 -> 10.783476 | J28: =I31 -> 9.7501734 | K28: =J31 -> 8.553879 | ... N28: =M31 -> 5.622672 | O28: =C28 -> 14.381468 | P28: Calculated value (simulated inputs) | Q28: Prior month's closing value
A29: Average cost per available unit | B29: $/unit | C29: =IFERROR((C28+C26)/C16,0) -> 0.24367713 | D29: =IFERROR((D28+D26)/D16,0) -> 0.24213778 | E29: =IFERROR((E28+E26)/E16,0) -> 0.24140283 | F29: =IFERROR((F28+F26)/F16,0) -> 0.24104063 | G29: =IFERROR((G28+G26)/G16,0) -> 0.24087191 | H29: =IFERROR((H28+H26)/H16,0) -> 0.2407946 | I29: =IFERROR((I28+I26)/I16,0) -> 0.24075963 | J29: =IFERROR((J28+J26)/J16,0) -> 0.24074482 | ... N29: =IFERROR((N28+N26)/N16,0) -> 0.24073569 | P29: Calculated value (simulated inputs) | Q29: (Opening value + manufacturing cost) / available units - weighted-average costing
A30: Cost of revenue | B30: $m | C30: =C17*C29 -> 15.605785 | D30: =D17*D29 -> 15.837141 | E30: =E17*E29 -> 16.775889 | F30: =F17*F29 -> 16.25805 | G30: =G17*G29 -> 16.410778 | H30: =H17*H29 -> 16.897676 | I30: =I17*I29 -> 16.731191 | J30: =J17*J29 -> 16.894182 | ... N30: =N17*N29 -> 15.745437 | O30: =SUM(C30:N30) -> 197.181 | P30: Calculated value (simulated inputs) | Q30: Units sold x average cost
A31: Closing inventory value | B31: $m | C31: =C28+C26-C30 -> 14.47357 | D31: =D28+D26-D30 -> 14.334317 | E31: =E28+E26-E30 -> 13.256316 | F31: =F28+F26-F30 -> 12.696154 | G31: =G28+G26-G30 -> 11.983264 | H31: =H28+H26-H30 -> 10.783476 | I31: =I28+I26-I30 -> 9.7501734 | J31: =J28+J26-J30 -> 8.553879 | ... N31: =N28+N26-N30 -> 5.5751229 | O31: =N31 -> 5.5751229 | P31: Calculated value (simulated inputs) | Q31: Opening value + manufacturing cost - cost of revenue
A32: Contribution margin | B32: $m | C32: =C22-C17*IFERROR(C23/C13,0) -> 28.320436 | D32: =D22-D17*IFERROR(D23/D13,0) -> 28.922999 | E32: =E22-E17*IFERROR(E23/E13,0) -> 30.730686 | F32: =F22-F17*IFERROR(F23/F13,0) -> 29.826843 | G32: =G22-G17*IFERROR(G23/G13,0) -> 30.128124 | H32: =H22-H17*IFERROR(H23/H13,0) -> 31.031967 | I32: =I22-I17*IFERROR(I23/I13,0) -> 30.730686 | J32: =J22-J17*IFERROR(J23/J13,0) -> 31.031967 | ... N32: =N22-N17*IFERROR(N23/N13,0) -> 28.922999 | O32: =SUM(C32:N32) -> 361.53749 | P32: Calculated value (simulated inputs) | Q32: Revenue - units sold x variable cost per good unit (variable cost / yield)
A33: Contribution margin % | B33: % | C33: =IFERROR(C32/C22,0) -> 0.74446217 | D33: =IFERROR(D32/D22,0) -> 0.74446217 | E33: =IFERROR(E32/E22,0) -> 0.74446217 | F33: =IFERROR(F32/F22,0) -> 0.74446217 | G33: =IFERROR(G32/G22,0) -> 0.74446217 | H33: =IFERROR(H32/H22,0) -> 0.74446217 | I33: =IFERROR(I32/I22,0) -> 0.74446217 | J33: =IFERROR(J32/J22,0) -> 0.74446217 | ... O33: =IFERROR(O32/O22,0) -> 0.74446217 | P33: Calculated value (simulated inputs) | Q33: Contribution margin / revenue
A34: Gross profit | B34: $m | C34: =C22-C30 -> 22.435686 | D34: =D22-D30 -> 23.013723 | E34: =E22-E30 -> 24.503155 | F34: =F22-F30 -> 23.806904 | G34: =G22-G30 -> 24.058873 | H34: =H22-H30 -> 24.786064 | I34: =I22-I30 -> 24.547853 | J34: =J22-J30 -> 24.789558 | ... N34: =N22-N30 -> 23.105428 | O34: =SUM(C34:N34) -> 288.45481 | P34: Calculated value (simulated inputs) | Q34: Revenue - cost of revenue
A35: Gross margin % | B35: % | C35: =IFERROR(C34/C22,0) -> 0.58976914 | D35: =IFERROR(D34/D22,0) -> 0.59236065 | E35: =IFERROR(E34/E22,0) -> 0.59359792 | F35: =IFERROR(F34/F22,0) -> 0.59420769 | G35: =IFERROR(G34/G22,0) -> 0.59449174 | H35: =IFERROR(H34/H22,0) -> 0.59462189 | I35: =IFERROR(I34/I22,0) -> 0.59468076 | J35: =IFERROR(J34/J22,0) -> 0.5947057 | ... O35: =IFERROR(O34/O22,0) -> 0.59397351 | P35: Calculated value (simulated inputs) | Q35: Gross profit / revenue
A37: Signal-chain chips - Simulated data created for portfolio demonstration. It does not represent nonpublic Texas Instruments information.
A38: Seasonality factor | B38: x | C38: =Assumptions!C$73 -> 0.94 | D38: =Assumptions!D$73 -> 0.96 | E38: =Assumptions!E$73 -> 1.02 | F38: =Assumptions!F$73 -> 0.99 | G38: =Assumptions!G$73 -> 1 | H38: =Assumptions!H$73 -> 1.03 | I38: =Assumptions!I$73 -> 1.02 | J38: =Assumptions!J$73 -> 1.03 | ... N38: =Assumptions!N$73 -> 0.96 | O38: =SUM(C38:N38) -> 12 | P38: Calculated value (simulated inputs) | Q38: Link: Assumptions section E
A39: Customer demand | B39: m units | C39: =Assumptions!$D$63*C38/12 -> 40.448136 | D39: =Assumptions!$D$63*D38/12 -> 41.308734 | E39: =Assumptions!$D$63*E38/12 -> 43.89053 | F39: =Assumptions!$D$63*F38/12 -> 42.599632 | G39: =Assumptions!$D$63*G38/12 -> 43.029932 | H39: =Assumptions!$D$63*H38/12 -> 44.32083 | I39: =Assumptions!$D$63*I38/12 -> 43.89053 | J39: =Assumptions!$D$63*J38/12 -> 44.32083 | ... N39: =Assumptions!$D$63*N38/12 -> 41.308734 | O39: =SUM(C39:N39) -> 516.35918 | P39: Calculated value (simulated inputs) | Q39: FY2026 demand x seasonality / 12
A40: Internal final-test capacity | B40: m units | C40: =Assumptions!$D$47 -> 60 | D40: =Assumptions!$D$47 -> 60 | E40: =Assumptions!$D$47 -> 60 | F40: =Assumptions!$D$47 -> 60 | G40: =Assumptions!$D$47 -> 60 | H40: =Assumptions!$D$47 -> 60 | I40: =Assumptions!$D$47 -> 60 | J40: =Assumptions!$D$47 -> 60 | ... N40: =Assumptions!$D$47 -> 60 | O40: =SUM(C40:N40) -> 720 | P40: Calculated value (simulated inputs) | Q40: Monthly capacity (Assumptions D)
A41: Capacity utilization | B41: % | C41: =Assumptions!$D$66 -> 0.78 | D41: =Assumptions!$D$66 -> 0.78 | E41: =Assumptions!$D$66 -> 0.78 | F41: =Assumptions!$D$66 -> 0.78 | G41: =Assumptions!$D$66 -> 0.78 | H41: =Assumptions!$D$66 -> 0.78 | I41: =Assumptions!$D$66 -> 0.78 | J41: =Assumptions!$D$66 -> 0.78 | ... N41: =Assumptions!$D$66 -> 0.78 | O41: =IFERROR(O42/O40,0) -> 0.78 | P41: Calculated value (simulated inputs) | Q41: Scenario utilization. FY = units produced / capacity
A42: Units produced (tested) | B42: m units | C42: =C40*C41 -> 46.8 | D42: =D40*D41 -> 46.8 | E42: =E40*E41 -> 46.8 | F42: =F40*F41 -> 46.8 | G42: =G40*G41 -> 46.8 | H42: =H40*H41 -> 46.8 | I42: =I40*I41 -> 46.8 | J42: =J40*J41 -> 46.8 | ... N42: =N40*N41 -> 46.8 | O42: =SUM(C42:N42) -> 561.6 | P42: Calculated value (simulated inputs) | Q42: Capacity x utilization
...

Sheet Revenue
A1: Monthly Revenue Forecast - FY2026 (active scenario)
A2: Revenue by product line, units in millions, $m. Simulated data created for portfolio demonstration. It does not represent nonpublic Texas Instruments information.
A3: Simulated data created for portfolio demonstration. It does not represent nonpublic Texas Instruments information.
A4: Scenario shown: | B4: =Assumptions!$C$6 -> Base
A6: Line item | B6: Units | C6: =Ops_Model!C$6 -> 46023 | D6: =Ops_Model!D$6 -> 46054 | E6: =Ops_Model!E$6 -> 46082 | F6: =Ops_Model!F$6 -> 46113 | G6: =Ops_Model!G$6 -> 46143 | H6: =Ops_Model!H$6 -> 46174 | I6: =Ops_Model!I$6 -> 46204 | J6: =Ops_Model!J$6 -> 46235 | ... N6: =Ops_Model!N$6 -> 46357 | O6: FY2026 | P6: Q1 FY26 | Q6: Q2 FY26 | R6: Q3 FY26 | S6: Q4 FY26 | T6: FY2025 base | U6: FY26 vs FY25 | V6: Classification | W6: Formula
A7: Power-management chips
A8: Units sold | B8: m units | C8: =Ops_Model!C$17 -> 64.042882 | D8: =Ops_Model!D$17 -> 65.405496 | E8: =Ops_Model!E$17 -> 69.49334 | F8: =Ops_Model!F$17 -> 67.449418 | G8: =Ops_Model!G$17 -> 68.130725 | H8: =Ops_Model!H$17 -> 70.174647 | I8: =Ops_Model!I$17 -> 69.49334 | J8: =Ops_Model!J$17 -> 70.174647 | ... N8: =Ops_Model!N$17 -> 65.405496 | O8: =SUM(C8:N8) -> 817.5687 | P8: =SUM(C8:E8) -> 198.94172 | Q8: =SUM(F8:H8) -> 205.75479 | R8: =SUM(I8:K8) -> 211.20525 | S8: =SUM(L8:N8) -> 201.66695 | T8: =Assumptions!C$52 -> 698.77667 | U8: =IFERROR(O8/T8-1,"") -> 0.17 | V8: Calculated value (simulated inputs) | W8: Link: Ops_Model units sold
A9: Revenue | B9: $m | C9: =Ops_Model!C$22 -> 38.041472 | D9: =Ops_Model!D$22 -> 38.850865 | E9: =Ops_Model!E$22 -> 41.279044 | F9: =Ops_Model!F$22 -> 40.064954 | G9: =Ops_Model!G$22 -> 40.469651 | H9: =Ops_Model!H$22 -> 41.68374 | I9: =Ops_Model!I$22 -> 41.279044 | J9: =Ops_Model!J$22 -> 41.68374 | ... N9: =Ops_Model!N$22 -> 38.850865 | O9: =SUM(C9:N9) -> 485.63581 | P9: =SUM(C9:E9) -> 118.17138 | Q9: =SUM(F9:H9) -> 122.21834 | R9: =SUM(I9:K9) -> 125.45592 | S9: =SUM(L9:N9) -> 119.79017 | T9: =Assumptions!C$42 -> 419.266 | U9: =IFERROR(O9/T9-1,"") -> 0.1583 | V9: Calculated value (simulated inputs) | W9: Link: Ops_Model revenue
A10: Average selling price | B10: $/unit | C10: =IFERROR(C9/C8,0) -> 0.594 | D10: =IFERROR(D9/D8,0) -> 0.594 | E10: =IFERROR(E9/E8,0) -> 0.594 | F10: =IFERROR(F9/F8,0) -> 0.594 | G10: =IFERROR(G9/G8,0) -> 0.594 | H10: =IFERROR(H9/H8,0) -> 0.594 | I10: =IFERROR(I9/I8,0) -> 0.594 | J10: =IFERROR(J9/J8,0) -> 0.594 | ... T10: =IFERROR(T9/T8,0) -> 0.6 | V10: Calculated value (simulated inputs) | W10: Revenue / units sold
A12: Signal-chain chips
A13: Units sold | B13: m units | C13: =Ops_Model!C$47 -> 40.448136 | D13: =Ops_Model!D$47 -> 41.308734 | E13: =Ops_Model!E$47 -> 43.89053 | F13: =Ops_Model!F$47 -> 42.599632 | G13: =Ops_Model!G$47 -> 43.029932 | H13: =Ops_Model!H$47 -> 44.32083 | I13: =Ops_Model!I$47 -> 43.89053 | J13: =Ops_Model!J$47 -> 44.32083 | ... N13: =Ops_Model!N$47 -> 41.308734 | O13: =SUM(C13:N13) -> 516.35918 | P13: =SUM(C13:E13) -> 125.6474 | Q13: =SUM(F13:H13) -> 129.95039 | R13: =SUM(I13:K13) -> 133.39279 | S13: =SUM(L13:N13) -> 127.3686 | T13: =Assumptions!D$52 -> 441.33263 | U13: =IFERROR(O13/T13-1,"") -> 0.17 | V13: Calculated value (simulated inputs) | W13: Link: Ops_Model units sold
A14: Revenue | B14: $m | C14: =Ops_Model!C$52 -> 38.041472 | D14: =Ops_Model!D$52 -> 38.850865 | E14: =Ops_Model!E$52 -> 41.279044 | F14: =Ops_Model!F$52 -> 40.064954 | G14: =Ops_Model!G$52 -> 40.469651 | H14: =Ops_Model!H$52 -> 41.68374 | I14: =Ops_Model!I$52 -> 41.279044 | J14: =Ops_Model!J$52 -> 41.68374 | ... N14: =Ops_Model!N$52 -> 38.850865 | O14: =SUM(C14:N14) -> 485.63581 | P14: =SUM(C14:E14) -> 118.17138 | Q14: =SUM(F14:H14) -> 122.21834 | R14: =SUM(I14:K14) -> 125.45592 | S14: =SUM(L14:N14) -> 119.79017 | T14: =Assumptions!D$42 -> 419.266 | U14: =IFERROR(O14/T14-1,"") -> 0.1583 | V14: Calculated value (simulated inputs) | W14: Link: Ops_Model revenue
A15: Average selling price | B15: $/unit | C15: =IFERROR(C14/C13,0) -> 0.9405 | D15: =IFERROR(D14/D13,0) -> 0.9405 | E15: =IFERROR(E14/E13,0) -> 0.9405 | F15: =IFERROR(F14/F13,0) -> 0.9405 | G15: =IFERROR(G14/G13,0) -> 0.9405 | H15: =IFERROR(H14/H13,0) -> 0.9405 | I15: =IFERROR(I14/I13,0) -> 0.9405 | J15: =IFERROR(J14/J13,0) -> 0.9405 | ... T15: =IFERROR(T14/T13,0) -> 0.95 | V15: Calculated value (simulated inputs) | W15: Revenue / units sold
A17: Embedded processors
A18: Units sold | B18: m units | C18: =Ops_Model!C$77 -> 4.0549047 | D18: =Ops_Model!D$77 -> 4.1411793 | E18: =Ops_Model!E$77 -> 4.400003 | F18: =Ops_Model!F$77 -> 4.2705911 | G18: =Ops_Model!G$77 -> 4.3137284 | H18: =Ops_Model!H$77 -> 4.4431403 | I18: =Ops_Model!I$77 -> 4.400003 | J18: =Ops_Model!J$77 -> 4.4431403 | ... N18: =Ops_Model!N$77 -> 4.1411793 | O18: =SUM(C18:N18) -> 51.764741 | P18: =SUM(C18:E18) -> 12.596087 | Q18: =SUM(F18:H18) -> 13.02746 | R18: =SUM(I18:K18) -> 13.372558 | S18: =SUM(L18:N18) -> 12.768636 | T18: =Assumptions!E$52 -> 47.490588 | U18: =IFERROR(O18/T18-1,"") -> 0.09 | V18: Calculated value (simulated inputs) | W18: Link: Ops_Model units sold
A19: Revenue | B19: $m | C19: =Ops_Model!C$82 -> 13.648809 | D19: =Ops_Model!D$82 -> 13.939209 | E19: =Ops_Model!E$82 -> 14.81041 | F19: =Ops_Model!F$82 -> 14.37481 | G19: =Ops_Model!G$82 -> 14.52001 | H19: =Ops_Model!H$82 -> 14.95561 | I19: =Ops_Model!I$82 -> 14.81041 | J19: =Ops_Model!J$82 -> 14.95561 | ... N19: =Ops_Model!N$82 -> 13.939209 | O19: =SUM(C19:N19) -> 174.24012 | P19: =SUM(C19:E19) -> 42.398429 | Q19: =SUM(F19:H19) -> 43.85043 | R19: =SUM(I19:K19) -> 45.012031 | S19: =SUM(L19:N19) -> 42.979229 | T19: =Assumptions!E$42 -> 161.468 | U19: =IFERROR(O19/T19-1,"") -> 0.0791 | V19: Calculated value (simulated inputs) | W19: Link: Ops_Model revenue
